Workbook

Sheet 操作台
A1: 畅言议程生成器 · 操作台 | B1: 畅言议程生成器 · 操作台 | C1: 畅言议程生成器 · 操作台 | D1: 畅言议程生成器 · 操作台 | E1: 畅言议程生成器 · 操作台 | F1: 畅言议程生成器 · 操作台 | G1: 畅言议程生成器 · 操作台 | H1: 畅言议程生成器 · 操作台 | I1: 畅言议程生成器 · 操作台 | J1: 畅言议程生成器 · 操作台 | K1: 畅言议程生成器 · 操作台 | L1: 畅言议程生成器 · 操作台 | M1: 畅言议程生成器 · 操作台 | N1: 畅言议程生成器 · 操作台 | O1: 畅言议程生成器 · 操作台 | P1: 畅言议程生成器 · 操作台
A2: 畅言议程生成器 · 操作台 | B2: 畅言议程生成器 · 操作台 | C2: 畅言议程生成器 · 操作台 | D2: 畅言议程生成器 · 操作台 | E2: 畅言议程生成器 · 操作台 | F2: 畅言议程生成器 · 操作台 | G2: 畅言议程生成器 · 操作台 | H2: 畅言议程生成器 · 操作台 | I2: 畅言议程生成器 · 操作台 | J2: 畅言议程生成器 · 操作台 | K2: 畅言议程生成器 · 操作台 | L2: 畅言议程生成器 · 操作台 | M2: 畅言议程生成器 · 操作台 | N2: 畅言议程生成器 · 操作台 | O2: 畅言议程生成器 · 操作台 | P2: 畅言议程生成器 · 操作台 | Q2: {=_xlfn._xlws.SORT(_xlfn.UNIQUE(_xlfn._xlws.FILTER(模板库!$B$2:$B$1000,模板库!$B$2:$B$1000<>"")))} -> 常规例会模板
Q3: 即兴马拉松模板
A4: 议程来源 | B4: 议程模板 | C4: 议程模板 | D4: 议程模板 | E4: 模板选择 | F4: 常规例会模板 | G4: 常规例会模板 | H4: 常规例会模板 | I4: 常规例会模板 | J4: 常规例会模板 | L4: 黄色区域可编辑 · 切换来源不会清空手工修正 | M4: 黄色区域可编辑 · 切换来源不会清空手工修正 | N4: 黄色区域可编辑 · 切换来源不会清空手工修正 | O4: 黄色区域可编辑 · 切换来源不会清空手工修正 | P4: 黄色区域可编辑 · 切换来源不会清空手工修正
A6: 会议信息 | B6: 会议信息 | C6: 会议信息 | D6: 会议信息 | E6: 会议信息 | F6: 会议信息 | G6: 会议信息 | H6: 会议信息 | I6: 会议信息 | J6: 会议信息 | K6: 会议信息 | L6: 会议信息 | M6: 会议信息 | N6: 会议信息 | O6: 会议信息 | P6: 会议信息
A7: 期数 | B7: 782 | C7: 782 | D7: 782 | E7: 主题 | F7: 复盘：我过的怎么样 | G7: 复盘：我过的怎么样 | H7: 复盘：我过的怎么样 | I7: 今日一词 | J7: 看见 | K7: 看见 | L7: 看见 | M7: 例会经理 | N7: 斯敏 | O7: 斯敏 | P7: 斯敏
A10: 日期 | B10: 46203 | C10: 46203 | D10: 46203 | E10: 开始时间 | F10: 0.80555556 | G10: 0.80555556 | H10: 0.80555556 | I10: 结束时间 | J10: 0.89583333 | K10: 0.89583333 | L10: 0.89583333 | N10: A4 页会根据来源选择解析字段或本页输入 | O10: A4 页会根据来源选择解析字段或本页输入 | P10: A4 页会根据来源选择解析字段或本页输入
A13: 地点 | B13: 深圳市南山区科技园讯美科技广场3号楼4楼SPACE MAX会议室(高新中A出口) | C13: 深圳市南山区科技园讯美科技广场3号楼4楼SPACE MAX会议室(高新中A出口) | D13: 深圳市南山区科技园讯美科技广场3号楼4楼SPACE MAX会议室(高新中A出口) | E13: 深圳市南山区科技园讯美科技广场3号楼4楼SPACE MAX会议室(高新中A出口) | F13: 深圳市南山区科技园讯美科技广场3号楼4楼SPACE MAX会议室(高新中A出口) | G13: 深圳市南山区科技园讯美科技广场3号楼4楼SPACE MAX会议室(高新中A出口) | H13: 深圳市南山区科技园讯美科技广场3号楼4楼SPACE MAX会议室(高新中A出口) | I13: 深圳市南山区科技园讯美科技广场3号楼4楼SPACE MAX会议室(高新中A出口) | J13: 深圳市南山区科技园讯美科技广场3号楼4楼SPACE MAX会议室(高新中A出口) | K13: 深圳市南山区科技园讯美科技广场3号楼4楼SPACE MAX会议室(高新中A出口) | L13: 深圳市南山区科技园讯美科技广场3号楼4楼SPACE MAX会议室(高新中A出口) | M13: 深圳市南山区科技园讯美科技广场3号楼4楼SPACE MAX会议室(高新中A出口) | N13: 深圳市南山区科技园讯美科技广场3号楼4楼SPACE MAX会议室(高新中A出口) | O13: 深圳市南山区科技园讯美科技广场3号楼4楼SPACE MAX会议室(高新中A出口) | P13: 深圳市南山区科技园讯美科技广场3号楼4楼SPACE MAX会议室(高新中A出口)
B14: 深圳市南山区科技园讯美科技广场3号楼4楼SPACE MAX会议室(高新中A出口) | C14: 深圳市南山区科技园讯美科技广场3号楼4楼SPACE MAX会议室(高新中A出口) | D14: 深圳市南山区科技园讯美科技广场3号楼4楼SPACE MAX会议室(高新中A出口) | E14: 深圳市南山区科技园讯美科技广场3号楼4楼SPACE MAX会议室(高新中A出口) | F14: 深圳市南山区科技园讯美科技广场3号楼4楼SPACE MAX会议室(高新中A出口) | G14: 深圳市南山区科技园讯美科技广场3号楼4楼SPACE MAX会议室(高新中A出口) | H14: 深圳市南山区科技园讯美科技广场3号楼4楼SPACE MAX会议室(高新中A出口) | I14: 深圳市南山区科技园讯美科技广场3号楼4楼SPACE MAX会议室(高新中A出口) | J14: 深圳市南山区科技园讯美科技广场3号楼4楼SPACE MAX会议室(高新中A出口) | K14: 深圳市南山区科技园讯美科技广场3号楼4楼SPACE MAX会议室(高新中A出口) | L14: 深圳市南山区科技园讯美科技广场3号楼4楼SPACE MAX会议室(高新中A出口) | M14: 深圳市南山区科技园讯美科技广场3号楼4楼SPACE MAX会议室(高新中A出口) | N14: 深圳市南山区科技园讯美科技广场3号楼4楼SPACE MAX会议室(高新中A出口) | O14: 深圳市南山区科技园讯美科技广场3号楼4楼SPACE MAX会议室(高新中A出口) | P14: 深圳市南山区科技园讯美科技广场3号楼4楼SPACE MAX会议室(高新中A出口)
A16: 微信接龙粘贴区（已预置 779 期验收样例，可直接替换） | B16: 微信接龙粘贴区（已预置 779 期验收样例，可直接替换） | C16: 微信接龙粘贴区（已预置 779 期验收样例，可直接替换） | D16: 微信接龙粘贴区（已预置 779 期验收样例，可直接替换） | E16: 微信接龙粘贴区（已预置 779 期验收样例，可直接替换） | F16: 微信接龙粘贴区（已预置 779 期验收样例，可直接替换） | G16: 微信接龙粘贴区（已预置 779 期验收样例，可直接替换） | H16: 微信接龙粘贴区（已预置 779 期验收样例，可直接替换） | I16: 微信接龙粘贴区（已预置 779 期验收样例，可直接替换） | J16: 微信接龙粘贴区（已预置 779 期验收样例，可直接替换） | L16: 解析预览 | M16: 解析预览 | N16: 解析预览 | O16: 解析预览 | P16: 解析预览
B18: @所有人 [烟花]畅言779期报名帖[烟花] 主题：志愿者 今日一词：服务 例会经理：莫婷 时间：6月9日 19:30-21:30 地点: 深圳南山•讯美科技3号楼4楼Space Max会议室 事务官开场：文星 主席致辞：卡卡 总主持：simon 来宾介绍：VPM 时间官：May 哼哈官：Jessica 语法官：莫婷 提问官：文星 即兴主持：莫婷 备稿演讲1：卡卡 备稿演讲2：史迪仔 备稿演讲3：[玫瑰] 即兴点评：女侠 备稿点评1：Jessica 备稿点评2：聪聪 备稿点评3：[玫瑰] 总点评：思玮 颁奖&真情分享：卡卡 拍照侠：ALL | C18: @所有人 [烟花]畅言779期报名帖[烟花] 主题：志愿者 今日一词：服务 例会经理：莫婷 时间：6月9日 19:30-21:30 地点: 深圳南山•讯美科技3号楼4楼Space Max会议室 事务官开场：文星 主席致辞：卡卡 总主持：simon 来宾介绍：VPM 时间官：May 哼哈官：Jessica 语法官：莫婷 提问官：文星 即兴主持：莫婷 备稿演讲1：卡卡 备稿演讲2：史迪仔 备稿演讲3：[玫瑰] 即兴点评：女侠 备稿点评1：Jessica 备稿点评2：聪聪 备稿点评3：[玫瑰] 总点评：思玮 颁奖&真情分享：卡卡 拍照侠：ALL | D18: @所有人 [烟花]畅言779期报名帖[烟花] 主题：志愿者 今日一词：服务 例会经理：莫婷 时间：6月9日 19:30-21:30 地点: 深圳南山•讯美科技3号楼4楼Space Max会议室 事务官开场：文星 主席致辞：卡卡 总主持：simon 来宾介绍：VPM 时间官：May 哼哈官：Jessica 语法官：莫婷 提问官：文星 即兴主持：莫婷 备稿演讲1：卡卡 备稿演讲2：史迪仔 备稿演讲3：[玫瑰] 即兴点评：女侠 备稿点评1：Jessica 备稿点评2：聪聪 备稿点评3：[玫瑰] 总点评：思玮 颁奖&真情分享：卡卡 拍照侠：ALL | E18: @所有人 [烟花]畅言779期报名帖[烟花] 主题：志愿者 今日一词：服务 例会经理：莫婷 时间：6月9日 19:30-21:30 地点: 深圳南山•讯美科技3号楼4楼Space Max会议室 事务官开场：文星 主席致辞：卡卡 总主持：simon 来宾介绍：VPM 时间官：May 哼哈官：Jessica 语法官：莫婷 提问官：文星 即兴主持：莫婷 备稿演讲1：卡卡 备稿演讲2：史迪仔 备稿演讲3：[玫瑰] 即兴点评：女侠 备稿点评1：Jessica 备稿点评2：聪聪 备稿点评3：[玫瑰] 总点评：思玮 颁奖&真情分享：卡卡 拍照侠：ALL | F18: @所有人 [烟花]畅言779期报名帖[烟花] 主题：志愿者 今日一词：服务 例会经理：莫婷 时间：6月9日 19:30-21:30 地点: 深圳南山•讯美科技3号楼4楼Space Max会议室 事务官开场：文星 主席致辞：卡卡 总主持：simon 来宾介绍：VPM 时间官：May 哼哈官：Jessica 语法官：莫婷 提问官：文星 即兴主持：莫婷 备稿演讲1：卡卡 备稿演讲2：史迪仔 备稿演讲3：[玫瑰] 即兴点评：女侠 备稿点评1：Jessica 备稿点评2：聪聪 备稿点评3：[玫瑰] 总点评：思玮 颁奖&真情分享：卡卡 拍照侠：ALL | G18: @所有人 [烟花]畅言779期报名帖[烟花] 主题：志愿者 今日一词：服务 例会经理：莫婷 时间：6月9日 19:30-21:30 地点: 深圳南山•讯美科技3号楼4楼Space Max会议室 事务官开场：文星 主席致辞：卡卡 总主持：simon 来宾介绍：VPM 时间官：May 哼哈官：Jessica 语法官：莫婷 提问官：文星 即兴主持：莫婷 备稿演讲1：卡卡 备稿演讲2：史迪仔 备稿演讲3：[玫瑰] 即兴点评：女侠 备稿点评1：Jessica 备稿点评2：聪聪 备稿点评3：[玫瑰] 总点评：思玮 颁奖&真情分享：卡卡 拍照侠：ALL | H18: @所有人 [烟花]畅言779期报名帖[烟花] 主题：志愿者 今日一词：服务 例会经理：莫婷 时间：6月9日 19:30-21:30 地点: 深圳南山•讯美科技3号楼4楼Space Max会议室 事务官开场：文星 主席致辞：卡卡 总主持：simon 来宾介绍：VPM 时间官：May 哼哈官：Jessica 语法官：莫婷 提问官：文星 即兴主持：莫婷 备稿演讲1：卡卡 备稿演讲2：史迪仔 备稿演讲3：[玫瑰] 即兴点评：女侠 备稿点评1：Jessica 备稿点评2：聪聪 备稿点评3：[玫瑰] 总点评：思玮 颁奖&真情分享：卡卡 拍照侠：ALL | I18: @所有人 [烟花]畅言779期报名帖[烟花] 主题：志愿者 今日一词：服务 例会经理：莫婷 时间：6月9日 19:30-21:30 地点: 深圳南山•讯美科技3号楼4楼Space Max会议室 事务官开场：文星 主席致辞：卡卡 总主持：simon 来宾介绍：VPM 时间官：May 哼哈官：Jessica 语法官：莫婷 提问官：文星 即兴主持：莫婷 备稿演讲1：卡卡 备稿演讲2：史迪仔 备稿演讲3：[玫瑰] 即兴点评：女侠 备稿点评1：Jessica 备稿点评2：聪聪 备稿点评3：[玫瑰] 总点评：思玮 颁奖&真情分享：卡卡 拍照侠：ALL | J18: @所有人 [烟花]畅言779期报名帖[烟花] 主题：志愿者 今日一词：服务 例会经理：莫婷 时间：6月9日 19:30-21:30 地点: 深圳南山•讯美科技3号楼4楼Space Max会议室 事务官开场：文星 主席致辞：卡卡 总主持：simon 来宾介绍：VPM 时间官：May 哼哈官：Jessica 语法官：莫婷 提问官：文星 即兴主持：莫婷 备稿演讲1：卡卡 备稿演讲2：史迪仔 备稿演讲3：[玫瑰] 即兴点评：女侠 备稿点评1：Jessica 备稿点评2：聪聪 备稿点评3：[玫瑰] 总点评：思玮 颁奖&真情分享：卡卡 拍照侠：ALL | L18: ="期数："&计算区!$E$2&" · 主题："&计算区!$E$3 -> 期数：779 · 主题：志愿者
B19: @所有人 [烟花]畅言779期报名帖[烟花] 主题：志愿者 今日一词：服务 例会经理：莫婷 时间：6月9日 19:30-21:30 地点: 深圳南山•讯美科技3号楼4楼Space Max会议室 事务官开场：文星 主席致辞：卡卡 总主持：simon 来宾介绍：VPM 时间官：May 哼哈官：Jessica 语法官：莫婷 提问官：文星 即兴主持：莫婷 备稿演讲1：卡卡 备稿演讲2：史迪仔 备稿演讲3：[玫瑰] 即兴点评：女侠 备稿点评1：Jessica 备稿点评2：聪聪 备稿点评3：[玫瑰] 总点评：思玮 颁奖&真情分享：卡卡 拍照侠：ALL | C19: @所有人 [烟花]畅言779期报名帖[烟花] 主题：志愿者 今日一词：服务 例会经理：莫婷 时间：6月9日 19:30-21:30 地点: 深圳南山•讯美科技3号楼4楼Space Max会议室 事务官开场：文星 主席致辞：卡卡 总主持：simon 来宾介绍：VPM 时间官：May 哼哈官：Jessica 语法官：莫婷 提问官：文星 即兴主持：莫婷 备稿演讲1：卡卡 备稿演讲2：史迪仔 备稿演讲3：[玫瑰] 即兴点评：女侠 备稿点评1：Jessica 备稿点评2：聪聪 备稿点评3：[玫瑰] 总点评：思玮 颁奖&真情分享：卡卡 拍照侠：ALL | D19: @所有人 [烟花]畅言779期报名帖[烟花] 主题：志愿者 今日一词：服务 例会经理：莫婷 时间：6月9日 19:30-21:30 地点: 深圳南山•讯美科技3号楼4楼Space Max会议室 事务官开场：文星 主席致辞：卡卡 总主持：simon 来宾介绍：VPM 时间官：May 哼哈官：Jessica 语法官：莫婷 提问官：文星 即兴主持：莫婷 备稿演讲1：卡卡 备稿演讲2：史迪仔 备稿演讲3：[玫瑰] 即兴点评：女侠 备稿点评1：Jessica 备稿点评2：聪聪 备稿点评3：[玫瑰] 总点评：思玮 颁奖&真情分享：卡卡 拍照侠：ALL | E19: @所有人 [烟花]畅言779期报名帖[烟花] 主题：志愿者 今日一词：服务 例会经理：莫婷 时间：6月9日 19:30-21:30 地点: 深圳南山•讯美科技3号楼4楼Space Max会议室 事务官开场：文星 主席致辞：卡卡 总主持：simon 来宾介绍：VPM 时间官：May 哼哈官：Jessica 语法官：莫婷 提问官：文星 即兴主持：莫婷 备稿演讲1：卡卡 备稿演讲2：史迪仔 备稿演讲3：[玫瑰] 即兴点评：女侠 备稿点评1：Jessica 备稿点评2：聪聪 备稿点评3：[玫瑰] 总点评：思玮 颁奖&真情分享：卡卡 拍照侠：ALL | F19: @所有人 [烟花]畅言779期报名帖[烟花] 主题：志愿者 今日一词：服务 例会经理：莫婷 时间：6月9日 19:30-21:30 地点: 深圳南山•讯美科技3号楼4楼Space Max会议室 事务官开场：文星 主席致辞：卡卡 总主持：simon 来宾介绍：VPM 时间官：May 哼哈官：Jessica 语法官：莫婷 提问官：文星 即兴主持：莫婷 备稿演讲1：卡卡 备稿演讲2：史迪仔 备稿演讲3：[玫瑰] 即兴点评：女侠 备稿点评1：Jessica 备稿点评2：聪聪 备稿点评3：[玫瑰] 总点评：思玮 颁奖&真情分享：卡卡 拍照侠：ALL | G19: @所有人 [烟花]畅言779期报名帖[烟花] 主题：志愿者 今日一词：服务 例会经理：莫婷 时间：6月9日 19:30-21:30 地点: 深圳南山•讯美科技3号楼4楼Space Max会议室 事务官开场：文星 主席致辞：卡卡 总主持：simon 来宾介绍：VPM 时间官：May 哼哈官：Jessica 语法官：莫婷 提问官：文星 即兴主持：莫婷 备稿演讲1：卡卡 备稿演讲2：史迪仔 备稿演讲3：[玫瑰] 即兴点评：女侠 备稿点评1：Jessica 备稿点评2：聪聪 备稿点评3：[玫瑰] 总点评：思玮 颁奖&真情分享：卡卡 拍照侠：ALL | H19: @所有人 [烟花]畅言779期报名帖[烟花] 主题：志愿者 今日一词：服务 例会经理：莫婷 时间：6月9日 19:30-21:30 地点: 深圳南山•讯美科技3号楼4楼Space Max会议室 事务官开场：文星 主席致辞：卡卡 总主持：simon 来宾介绍：VPM 时间官：May 哼哈官：Jessica 语法官：莫婷 提问官：文星 即兴主持：莫婷 备稿演讲1：卡卡 备稿演讲2：史迪仔 备稿演讲3：[玫瑰] 即兴点评：女侠 备稿点评1：Jessica 备稿点评2：聪聪 备稿点评3：[玫瑰] 总点评：思玮 颁奖&真情分享：卡卡 拍照侠：ALL | I19: @所有人 [烟花]畅言779期报名帖[烟花] 主题：志愿者 今日一词：服务 例会经理：莫婷 时间：6月9日 19:30-21:30 地点: 深圳南山•讯美科技3号楼4楼Space Max会议室 事务官开场：文星 主席致辞：卡卡 总主持：simon 来宾介绍：VPM 时间官：May 哼哈官：Jessica 语法官：莫婷 提问官：文星 即兴主持：莫婷 备稿演讲1：卡卡 备稿演讲2：史迪仔 备稿演讲3：[玫瑰] 即兴点评：女侠 备稿点评1：Jessica 备稿点评2：聪聪 备稿点评3：[玫瑰] 总点评：思玮 颁奖&真情分享：卡卡 拍照侠：ALL | J19: @所有人 [烟花]畅言779期报名帖[烟花] 主题：志愿者 今日一词：服务 例会经理：莫婷 时间：6月9日 19:30-21:30 地点: 深圳南山•讯美科技3号楼4楼Space Max会议室 事务官开场：文星 主席致辞：卡卡 总主持：simon 来宾介绍：VPM 时间官：May 哼哈官：Jessica 语法官：莫婷 提问官：文星 即兴主持：莫婷 备稿演讲1：卡卡 备稿演讲2：史迪仔 备稿演讲3：[玫瑰] 即兴点评：女侠 备稿点评1：Jessica 备稿点评2：聪聪 备稿点评3：[玫瑰] 总点评：思玮 颁奖&真情分享：卡卡 拍照侠：ALL
B20: @所有人 [烟花]畅言779期报名帖[烟花] 主题：志愿者 今日一词：服务 例会经理：莫婷 时间：6月9日 19:30-21:30 地点: 深圳南山•讯美科技3号楼4楼Space Max会议室 事务官开场：文星 主席致辞：卡卡 总主持：simon 来宾介绍：VPM 时间官：May 哼哈官：Jessica 语法官：莫婷 提问官：文星 即兴主持：莫婷 备稿演讲1：卡卡 备稿演讲2：史迪仔 备稿演讲3：[玫瑰] 即兴点评：女侠 备稿点评1：Jessica 备稿点评2：聪聪 备稿点评3：[玫瑰] 总点评：思玮 颁奖&真情分享：卡卡 拍照侠：ALL | C20: @所有人 [烟花]畅言779期报名帖[烟花] 主题：志愿者 今日一词：服务 例会经理：莫婷 时间：6月9日 19:30-21:30 地点: 深圳南山•讯美科技3号楼4楼Space Max会议室 事务官开场：文星 主席致辞：卡卡 总主持：simon 来宾介绍：VPM 时间官：May 哼哈官：Jessica 语法官：莫婷 提问官：文星 即兴主持：莫婷 备稿演讲1：卡卡 备稿演讲2：史迪仔 备稿演讲3：[玫瑰] 即兴点评：女侠 备稿点评1：Jessica 备稿点评2：聪聪 备稿点评3：[玫瑰] 总点评：思玮 颁奖&真情分享：卡卡 拍照侠：ALL | D20: @所有人 [烟花]畅言779期报名帖[烟花] 主题：志愿者 今日一词：服务 例会经理：莫婷 时间：6月9日 19:30-21:30 地点: 深圳南山•讯美科技3号楼4楼Space Max会议室 事务官开场：文星 主席致辞：卡卡 总主持：simon 来宾介绍：VPM 时间官：May 哼哈官：Jessica 语法官：莫婷 提问官：文星 即兴主持：莫婷 备稿演讲1：卡卡 备稿演讲2：史迪仔 备稿演讲3：[玫瑰] 即兴点评：女侠 备稿点评1：Jessica 备稿点评2：聪聪 备稿点评3：[玫瑰] 总点评：思玮 颁奖&真情分享：卡卡 拍照侠：ALL | E20: @所有人 [烟花]畅言779期报名帖[烟花] 主题：志愿者 今日一词：服务 例会经理：莫婷 时间：6月9日 19:30-21:30 地点: 深圳南山•讯美科技3号楼4楼Space Max会议室 事务官开场：文星 主席致辞：卡卡 总主持：simon 来宾介绍：VPM 时间官：May 哼哈官：Jessica 语法官：莫婷 提问官：文星 即兴主持：莫婷 备稿演讲1：卡卡 备稿演讲2：史迪仔 备稿演讲3：[玫瑰] 即兴点评：女侠 备稿点评1：Jessica 备稿点评2：聪聪 备稿点评3：[玫瑰] 总点评：思玮 颁奖&真情分享：卡卡 拍照侠：ALL | F20: @所有人 [烟花]畅言779期报名帖[烟花] 主题：志愿者 今日一词：服务 例会经理：莫婷 时间：6月9日 19:30-21:30 地点: 深圳南山•讯美科技3号楼4楼Space Max会议室 事务官开场：文星 主席致辞：卡卡 总主持：simon 来宾介绍：VPM 时间官：May 哼哈官：Jessica 语法官：莫婷 提问官：文星 即兴主持：莫婷 备稿演讲1：卡卡 备稿演讲2：史迪仔 备稿演讲3：[玫瑰] 即兴点评：女侠 备稿点评1：Jessica 备稿点评2：聪聪 备稿点评3：[玫瑰] 总点评：思玮 颁奖&真情分享：卡卡 拍照侠：ALL | G20: @所有人 [烟花]畅言779期报名帖[烟花] 主题：志愿者 今日一词：服务 例会经理：莫婷 时间：6月9日 19:30-21:30 地点: 深圳南山•讯美科技3号楼4楼Space Max会议室 事务官开场：文星 主席致辞：卡卡 总主持：simon 来宾介绍：VPM 时间官：May 哼哈官：Jessica 语法官：莫婷 提问官：文星 即兴主持：莫婷 备稿演讲1：卡卡 备稿演讲2：史迪仔 备稿演讲3：[玫瑰] 即兴点评：女侠 备稿点评1：Jessica 备稿点评2：聪聪 备稿点评3：[玫瑰] 总点评：思玮 颁奖&真情分享：卡卡 拍照侠：ALL | H20: @所有人 [烟花]畅言779期报名帖[烟花] 主题：志愿者 今日一词：服务 例会经理：莫婷 时间：6月9日 19:30-21:30 地点: 深圳南山•讯美科技3号楼4楼Space Max会议室 事务官开场：文星 主席致辞：卡卡 总主持：simon 来宾介绍：VPM 时间官：May 哼哈官：Jessica 语法官：莫婷 提问官：文星 即兴主持：莫婷 备稿演讲1：卡卡 备稿演讲2：史迪仔 备稿演讲3：[玫瑰] 即兴点评：女侠 备稿点评1：Jessica 备稿点评2：聪聪 备稿点评3：[玫瑰] 总点评：思玮 颁奖&真情分享：卡卡 拍照侠：ALL | I20: @所有人 [烟花]畅言779期报名帖[烟花] 主题：志愿者 今日一词：服务 例会经理：莫婷 时间：6月9日 19:30-21:30 地点: 深圳南山•讯美科技3号楼4楼Space Max会议室 事务官开场：文星 主席致辞：卡卡 总主持：simon 来宾介绍：VPM 时间官：May 哼哈官：Jessica 语法官：莫婷 提问官：文星 即兴主持：莫婷 备稿演讲1：卡卡 备稿演讲2：史迪仔 备稿演讲3：[玫瑰] 即兴点评：女侠 备稿点评1：Jessica 备稿点评2：聪聪 备稿点评3：[玫瑰] 总点评：思玮 颁奖&真情分享：卡卡 拍照侠：ALL | J20: @所有人 [烟花]畅言779期报名帖[烟花] 主题：志愿者 今日一词：服务 例会经理：莫婷 时间：6月9日 19:30-21:30 地点: 深圳南山•讯美科技3号楼4楼Space Max会议室 事务官开场：文星 主席致辞：卡卡 总主持：simon 来宾介绍：VPM 时间官：May 哼哈官：Jessica 语法官：莫婷 提问官：文星 即兴主持：莫婷 备稿演讲1：卡卡 备稿演讲2：史迪仔 备稿演讲3：[玫瑰] 即兴点评：女侠 备稿点评1：Jessica 备稿点评2：聪聪 备稿点评3：[玫瑰] 总点评：思玮 颁奖&真情分享：卡卡 拍照侠：ALL | L20: ="今日一词："&计算区!$E$4&" · 经理："&计算区!$E$5 -> 今日一词：服务 · 经理：莫婷
B21: @所有人 [烟花]畅言779期报名帖[烟花] 主题：志愿者 今日一词：服务 例会经理：莫婷 时间：6月9日 19:30-21:30 地点: 深圳南山•讯美科技3号楼4楼Space Max会议室 事务官开场：文星 主席致辞：卡卡 总主持：simon 来宾介绍：VPM 时间官：May 哼哈官：Jessica 语法官：莫婷 提问官：文星 即兴主持：莫婷 备稿演讲1：卡卡 备稿演讲2：史迪仔 备稿演讲3：[玫瑰] 即兴点评：女侠 备稿点评1：Jessica 备稿点评2：聪聪 备稿点评3：[玫瑰] 总点评：思玮 颁奖&真情分享：卡卡 拍照侠：ALL | C21: @所有人 [烟花]畅言779期报名帖[烟花] 主题：志愿者 今日一词：服务 例会经理：莫婷 时间：6月9日 19:30-21:30 地点: 深圳南山•讯美科技3号楼4楼Space Max会议室 事务官开场：文星 主席致辞：卡卡 总主持：simon 来宾介绍：VPM 时间官：May 哼哈官：Jessica 语法官：莫婷 提问官：文星 即兴主持：莫婷 备稿演讲1：卡卡 备稿演讲2：史迪仔 备稿演讲3：[玫瑰] 即兴点评：女侠 备稿点评1：Jessica 备稿点评2：聪聪 备稿点评3：[玫瑰] 总点评：思玮 颁奖&真情分享：卡卡 拍照侠：ALL | D21: @所有人 [烟花]畅言779期报名帖[烟花] 主题：志愿者 今日一词：服务 例会经理：莫婷 时间：6月9日 19:30-21:30 地点: 深圳南山•讯美科技3号楼4楼Space Max会议室 事务官开场：文星 主席致辞：卡卡 总主持：simon 来宾介绍：VPM 时间官：May 哼哈官：Jessica 语法官：莫婷 提问官：文星 即兴主持：莫婷 备稿演讲1：卡卡 备稿演讲2：史迪仔 备稿演讲3：[玫瑰] 即兴点评：女侠 备稿点评1：Jessica 备稿点评2：聪聪 备稿点评3：[玫瑰] 总点评：思玮 颁奖&真情分享：卡卡 拍照侠：ALL | E21: @所有人 [烟花]畅言779期报名帖[烟花] 主题：志愿者 今日一词：服务 例会经理：莫婷 时间：6月9日 19:30-21:30 地点: 深圳南山•讯美科技3号楼4楼Space Max会议室 事务官开场：文星 主席致辞：卡卡 总主持：simon 来宾介绍：VPM 时间官：May 哼哈官：Jessica 语法官：莫婷 提问官：文星 即兴主持：莫婷 备稿演讲1：卡卡 备稿演讲2：史迪仔 备稿演讲3：[玫瑰] 即兴点评：女侠 备稿点评1：Jessica 备稿点评2：聪聪 备稿点评3：[玫瑰] 总点评：思玮 颁奖&真情分享：卡卡 拍照侠：ALL | F21: @所有人 [烟花]畅言779期报名帖[烟花] 主题：志愿者 今日一词：服务 例会经理：莫婷 时间：6月9日 19:30-21:30 地点: 深圳南山•讯美科技3号楼4楼Space Max会议室 事务官开场：文星 主席致辞：卡卡 总主持：simon 来宾介绍：VPM 时间官：May 哼哈官：Jessica 语法官：莫婷 提问官：文星 即兴主持：莫婷 备稿演讲1：卡卡 备稿演讲2：史迪仔 备稿演讲3：[玫瑰] 即兴点评：女侠 备稿点评1：Jessica 备稿点评2：聪聪 备稿点评3：[玫瑰] 总点评：思玮 颁奖&真情分享：卡卡 拍照侠：ALL | G21: @所有人 [烟花]畅言779期报名帖[烟花] 主题：志愿者 今日一词：服务 例会经理：莫婷 时间：6月9日 19:30-21:30 地点: 深圳南山•讯美科技3号楼4楼Space Max会议室 事务官开场：文星 主席致辞：卡卡 总主持：simon 来宾介绍：VPM 时间官：May 哼哈官：Jessica 语法官：莫婷 提问官：文星 即兴主持：莫婷 备稿演讲1：卡卡 备稿演讲2：史迪仔 备稿演讲3：[玫瑰] 即兴点评：女侠 备稿点评1：Jessica 备稿点评2：聪聪 备稿点评3：[玫瑰] 总点评：思玮 颁奖&真情分享：卡卡 拍照侠：ALL | H21: @所有人 [烟花]畅言779期报名帖[烟花] 主题：志愿者 今日一词：服务 例会经理：莫婷 时间：6月9日 19:30-21:30 地点: 深圳南山•讯美科技3号楼4楼Space Max会议室 事务官开场：文星 主席致辞：卡卡 总主持：simon 来宾介绍：VPM 时间官：May 哼哈官：Jessica 语法官：莫婷 提问官：文星 即兴主持：莫婷 备稿演讲1：卡卡 备稿演讲2：史迪仔 备稿演讲3：[玫瑰] 即兴点评：女侠 备稿点评1：Jessica 备稿点评2：聪聪 备稿点评3：[玫瑰] 总点评：思玮 颁奖&真情分享：卡卡 拍照侠：ALL | I21: @所有人 [烟花]畅言779期报名帖[烟花] 主题：志愿者 今日一词：服务 例会经理：莫婷 时间：6月9日 19:30-21:30 地点: 深圳南山•讯美科技3号楼4楼Space Max会议室 事务官开场：文星 主席致辞：卡卡 总主持：simon 来宾介绍：VPM 时间官：May 哼哈官：Jessica 语法官：莫婷 提问官：文星 即兴主持：莫婷 备稿演讲1：卡卡 备稿演讲2：史迪仔 备稿演讲3：[玫瑰] 即兴点评：女侠 备稿点评1：Jessica 备稿点评2：聪聪 备稿点评3：[玫瑰] 总点评：思玮 颁奖&真情分享：卡卡 拍照侠：ALL | J21: @所有人 [烟花]畅言779期报名帖[烟花] 主题：志愿者 今日一词：服务 例会经理：莫婷 时间：6月9日 19:30-21:30 地点: 深圳南山•讯美科技3号楼4楼Space Max会议室 事务官开场：文星 主席致辞：卡卡 总主持：simon 来宾介绍：VPM 时间官：May 哼哈官：Jessica 语法官：莫婷 提问官：文星 即兴主持：莫婷 备稿演讲1：卡卡 备稿演讲2：史迪仔 备稿演讲3：[玫瑰] 即兴点评：女侠 备稿点评1：Jessica 备稿点评2：聪聪 备稿点评3：[玫瑰] 总点评：思玮 颁奖&真情分享：卡卡 拍照侠：ALL | L21: =IF(计算区!$E$6="","日期/时间：待检查","日期/时间："&TEXT(计算区!$E$6,"yyyy-mm-dd")&" "&TEXT(计算区!$E$7,"hh:mm")&"–"&TEXT(计算区!$E$8,"hh:mm")) -> 日期/时间：2026-06-09 19:30–21:30
B22: @所有人 [烟花]畅言779期报名帖[烟花] 主题：志愿者 今日一词：服务 例会经理：莫婷 时间：6月9日 19:30-21:30 地点: 深圳南山•讯美科技3号楼4楼Space Max会议室 事务官开场：文星 主席致辞：卡卡 总主持：simon 来宾介绍：VPM 时间官：May 哼哈官：Jessica 语法官：莫婷 提问官：文星 即兴主持：莫婷 备稿演讲1：卡卡 备稿演讲2：史迪仔 备稿演讲3：[玫瑰] 即兴点评：女侠 备稿点评1：Jessica 备稿点评2：聪聪 备稿点评3：[玫瑰] 总点评：思玮 颁奖&真情分享：卡卡 拍照侠：ALL | C22: @所有人 [烟花]畅言779期报名帖[烟花] 主题：志愿者 今日一词：服务 例会经理：莫婷 时间：6月9日 19:30-21:30 地点: 深圳南山•讯美科技3号楼4楼Space Max会议室 事务官开场：文星 主席致辞：卡卡 总主持：simon 来宾介绍：VPM 时间官：May 哼哈官：Jessica 语法官：莫婷 提问官：文星 即兴主持：莫婷 备稿演讲1：卡卡 备稿演讲2：史迪仔 备稿演讲3：[玫瑰] 即兴点评：女侠 备稿点评1：Jessica 备稿点评2：聪聪 备稿点评3：[玫瑰] 总点评：思玮 颁奖&真情分享：卡卡 拍照侠：ALL | D22: @所有人 [烟花]畅言779期报名帖[烟花] 主题：志愿者 今日一词：服务 例会经理：莫婷 时间：6月9日 19:30-21:30 地点: 深圳南山•讯美科技3号楼4楼Space Max会议室 事务官开场：文星 主席致辞：卡卡 总主持：simon 来宾介绍：VPM 时间官：May 哼哈官：Jessica 语法官：莫婷 提问官：文星 即兴主持：莫婷 备稿演讲1：卡卡 备稿演讲2：史迪仔 备稿演讲3：[玫瑰] 即兴点评：女侠 备稿点评1：Jessica 备稿点评2：聪聪 备稿点评3：[玫瑰] 总点评：思玮 颁奖&真情分享：卡卡 拍照侠：ALL | E22: @所有人 [烟花]畅言779期报名帖[烟花] 主题：志愿者 今日一词：服务 例会经理：莫婷 时间：6月9日 19:30-21:30 地点: 深圳南山•讯美科技3号楼4楼Space Max会议室 事务官开场：文星 主席致辞：卡卡 总主持：simon 来宾介绍：VPM 时间官：May 哼哈官：Jessica 语法官：莫婷 提问官：文星 即兴主持：莫婷 备稿演讲1：卡卡 备稿演讲2：史迪仔 备稿演讲3：[玫瑰] 即兴点评：女侠 备稿点评1：Jessica 备稿点评2：聪聪 备稿点评3：[玫瑰] 总点评：思玮 颁奖&真情分享：卡卡 拍照侠：ALL | F22: @所有人 [烟花]畅言779期报名帖[烟花] 主题：志愿者 今日一词：服务 例会经理：莫婷 时间：6月9日 19:30-21:30 地点: 深圳南山•讯美科技3号楼4楼Space Max会议室 事务官开场：文星 主席致辞：卡卡 总主持：simon 来宾介绍：VPM 时间官：May 哼哈官：Jessica 语法官：莫婷 提问官：文星 即兴主持：莫婷 备稿演讲1：卡卡 备稿演讲2：史迪仔 备稿演讲3：[玫瑰] 即兴点评：女侠 备稿点评1：Jessica 备稿点评2：聪聪 备稿点评3：[玫瑰] 总点评：思玮 颁奖&真情分享：卡卡 拍照侠：ALL | G22: @所有人 [烟花]畅言779期报名帖[烟花] 主题：志愿者 今日一词：服务 例会经理：莫婷 时间：6月9日 19:30-21:30 地点: 深圳南山•讯美科技3号楼4楼Space Max会议室 事务官开场：文星 主席致辞：卡卡 总主持：simon 来宾介绍：VPM 时间官：May 哼哈官：Jessica 语法官：莫婷 提问官：文星 即兴主持：莫婷 备稿演讲1：卡卡 备稿演讲2：史迪仔 备稿演讲3：[玫瑰] 即兴点评：女侠 备稿点评1：Jessica 备稿点评2：聪聪 备稿点评3：[玫瑰] 总点评：思玮 颁奖&真情分享：卡卡 拍照侠：ALL | H22: @所有人 [烟花]畅言779期报名帖[烟花] 主题：志愿者 今日一词：服务 例会经理：莫婷 时间：6月9日 19:30-21:30 地点: 深圳南山•讯美科技3号楼4楼Space Max会议室 事务官开场：文星 主席致辞：卡卡 总主持：simon 来宾介绍：VPM 时间官：May 哼哈官：Jessica 语法官：莫婷 提问官：文星 即兴主持：莫婷 备稿演讲1：卡卡 备稿演讲2：史迪仔 备稿演讲3：[玫瑰] 即兴点评：女侠 备稿点评1：Jessica 备稿点评2：聪聪 备稿点评3：[玫瑰] 总点评：思玮 颁奖&真情分享：卡卡 拍照侠：ALL | I22: @所有人 [烟花]畅言779期报名帖[烟花] 主题：志愿者 今日一词：服务 例会经理：莫婷 时间：6月9日 19:30-21:30 地点: 深圳南山•讯美科技3号楼4楼Space Max会议室 事务官开场：文星 主席致辞：卡卡 总主持：simon 来宾介绍：VPM 时间官：May 哼哈官：Jessica 语法官：莫婷 提问官：文星 即兴主持：莫婷 备稿演讲1：卡卡 备稿演讲2：史迪仔 备稿演讲3：[玫瑰] 即兴点评：女侠 备稿点评1：Jessica 备稿点评2：聪聪 备稿点评3：[玫瑰] 总点评：思玮 颁奖&真情分享：卡卡 拍照侠：ALL | J22: @所有人 [烟花]畅言779期报名帖[烟花] 主题：志愿者 今日一词：服务 例会经理：莫婷 时间：6月9日 19:30-21:30 地点: 深圳南山•讯美科技3号楼4楼Space Max会议室 事务官开场：文星 主席致辞：卡卡 总主持：simon 来宾介绍：VPM 时间官：May 哼哈官：Jessica 语法官：莫婷 提问官：文星 即兴主持：莫婷 备稿演讲1：卡卡 备稿演讲2：史迪仔 备稿演讲3：[玫瑰] 即兴点评：女侠 备稿点评1：Jessica 备稿点评2：聪聪 备稿点评3：[玫瑰] 总点评：思玮 颁奖&真情分享：卡卡 拍照侠：ALL
B23: @所有人 [烟花]畅言779期报名帖[烟花] 主题：志愿者 今日一词：服务 例会经理：莫婷 时间：6月9日 19:30-21:30 地点: 深圳南山•讯美科技3号楼4楼Space Max会议室 事务官开场：文星 主席致辞：卡卡 总主持：simon 来宾介绍：VPM 时间官：May 哼哈官：Jessica 语法官：莫婷 提问官：文星 即兴主持：莫婷 备稿演讲1：卡卡 备稿演讲2：史迪仔 备稿演讲3：[玫瑰] 即兴点评：女侠 备稿点评1：Jessica 备稿点评2：聪聪 备稿点评3：[玫瑰] 总点评：思玮 颁奖&真情分享：卡卡 拍照侠：ALL | C23: @所有人 [烟花]畅言779期报名帖[烟花] 主题：志愿者 今日一词：服务 例会经理：莫婷 时间：6月9日 19:30-21:30 地点: 深圳南山•讯美科技3号楼4楼Space Max会议室 事务官开场：文星 主席致辞：卡卡 总主持：simon 来宾介绍：VPM 时间官：May 哼哈官：Jessica 语法官：莫婷 提问官：文星 即兴主持：莫婷 备稿演讲1：卡卡 备稿演讲2：史迪仔 备稿演讲3：[玫瑰] 即兴点评：女侠 备稿点评1：Jessica 备稿点评2：聪聪 备稿点评3：[玫瑰] 总点评：思玮 颁奖&真情分享：卡卡 拍照侠：ALL | D23: @所有人 [烟花]畅言779期报名帖[烟花] 主题：志愿者 今日一词：服务 例会经理：莫婷 时间：6月9日 19:30-21:30 地点: 深圳南山•讯美科技3号楼4楼Space Max会议室 事务官开场：文星 主席致辞：卡卡 总主持：simon 来宾介绍：VPM 时间官：May 哼哈官：Jessica 语法官：莫婷 提问官：文星 即兴主持：莫婷 备稿演讲1：卡卡 备稿演讲2：史迪仔 备稿演讲3：[玫瑰] 即兴点评：女侠 备稿点评1：Jessica 备稿点评2：聪聪 备稿点评3：[玫瑰] 总点评：思玮 颁奖&真情分享：卡卡 拍照侠：ALL | E23: @所有人 [烟花]畅言779期报名帖[烟花] 主题：志愿者 今日一词：服务 例会经理：莫婷 时间：6月9日 19:30-21:30 地点: 深圳南山•讯美科技3号楼4楼Space Max会议室 事务官开场：文星 主席致辞：卡卡 总主持：simon 来宾介绍：VPM 时间官：May 哼哈官：Jessica 语法官：莫婷 提问官：文星 即兴主持：莫婷 备稿演讲1：卡卡 备稿演讲2：史迪仔 备稿演讲3：[玫瑰] 即兴点评：女侠 备稿点评1：Jessica 备稿点评2：聪聪 备稿点评3：[玫瑰] 总点评：思玮 颁奖&真情分享：卡卡 拍照侠：ALL | F23: @所有人 [烟花]畅言779期报名帖[烟花] 主题：志愿者 今日一词：服务 例会经理：莫婷 时间：6月9日 19:30-21:30 地点: 深圳南山•讯美科技3号楼4楼Space Max会议室 事务官开场：文星 主席致辞：卡卡 总主持：simon 来宾介绍：VPM 时间官：May 哼哈官：Jessica 语法官：莫婷 提问官：文星 即兴主持：莫婷 备稿演讲1：卡卡 备稿演讲2：史迪仔 备稿演讲3：[玫瑰] 即兴点评：女侠 备稿点评1：Jessica 备稿点评2：聪聪 备稿点评3：[玫瑰] 总点评：思玮 颁奖&真情分享：卡卡 拍照侠：ALL | G23: @所有人 [烟花]畅言779期报名帖[烟花] 主题：志愿者 今日一词：服务 例会经理：莫婷 时间：6月9日 19:30-21:30 地点: 深圳南山•讯美科技3号楼4楼Space Max会议室 事务官开场：文星 主席致辞：卡卡 总主持：simon 来宾介绍：VPM 时间官：May 哼哈官：Jessica 语法官：莫婷 提问官：文星 即兴主持：莫婷 备稿演讲1：卡卡 备稿演讲2：史迪仔 备稿演讲3：[玫瑰] 即兴点评：女侠 备稿点评1：Jessica 备稿点评2：聪聪 备稿点评3：[玫瑰] 总点评：思玮 颁奖&真情分享：卡卡 拍照侠：ALL | H23: @所有人 [烟花]畅言779期报名帖[烟花] 主题：志愿者 今日一词：服务 例会经理：莫婷 时间：6月9日 19:30-21:30 地点: 深圳南山•讯美科技3号楼4楼Space Max会议室 事务官开场：文星 主席致辞：卡卡 总主持：simon 来宾介绍：VPM 时间官：May 哼哈官：Jessica 语法官：莫婷 提问官：文星 即兴主持：莫婷 备稿演讲1：卡卡 备稿演讲2：史迪仔 备稿演讲3：[玫瑰] 即兴点评：女侠 备稿点评1：Jessica 备稿点评2：聪聪 备稿点评3：[玫瑰] 总点评：思玮 颁奖&真情分享：卡卡 拍照侠：ALL | I23: @所有人 [烟花]畅言779期报名帖[烟花] 主题：志愿者 今日一词：服务 例会经理：莫婷 时间：6月9日 19:30-21:30 地点: 深圳南山•讯美科技3号楼4楼Space Max会议室 事务官开场：文星 主席致辞：卡卡 总主持：simon 来宾介绍：VPM 时间官：May 哼哈官：Jessica 语法官：莫婷 提问官：文星 即兴主持：莫婷 备稿演讲1：卡卡 备稿演讲2：史迪仔 备稿演讲3：[玫瑰] 即兴点评：女侠 备稿点评1：Jessica 备稿点评2：聪聪 备稿点评3：[玫瑰] 总点评：思玮 颁奖&真情分享：卡卡 拍照侠：ALL | J23: @所有人 [烟花]畅言779期报名帖[烟花] 主题：志愿者 今日一词：服务 例会经理：莫婷 时间：6月9日 19:30-21:30 地点: 深圳南山•讯美科技3号楼4楼Space Max会议室 事务官开场：文星 主席致辞：卡卡 总主持：simon 来宾介绍：VPM 时间官：May 哼哈官：Jessica 语法官：莫婷 提问官：文星 即兴主持：莫婷 备稿演讲1：卡卡 备稿演讲2：史迪仔 备稿演讲3：[玫瑰] 即兴点评：女侠 备稿点评1：Jessica 备稿点评2：聪聪 备稿点评3：[玫瑰] 总点评：思玮 颁奖&真情分享：卡卡 拍照侠：ALL | L23: ="地点："&计算区!$E$9 -> 地点：深圳南山•讯美科技3号楼4楼Space Max会议室
B24: @所有人 [烟花]畅言779期报名帖[烟花] 主题：志愿者 今日一词：服务 例会经理：莫婷 时间：6月9日 19:30-21:30 地点: 深圳南山•讯美科技3号楼4楼Space Max会议室 事务官开场：文星 主席致辞：卡卡 总主持：simon 来宾介绍：VPM 时间官：May 哼哈官：Jessica 语法官：莫婷 提问官：文星 即兴主持：莫婷 备稿演讲1：卡卡 备稿演讲2：史迪仔 备稿演讲3：[玫瑰] 即兴点评：女侠 备稿点评1：Jessica 备稿点评2：聪聪 备稿点评3：[玫瑰] 总点评：思玮 颁奖&真情分享：卡卡 拍照侠：ALL | C24: @所有人 [烟花]畅言779期报名帖[烟花] 主题：志愿者 今日一词：服务 例会经理：莫婷 时间：6月9日 19:30-21:30 地点: 深圳南山•讯美科技3号楼4楼Space Max会议室 事务官开场：文星 主席致辞：卡卡 总主持：simon 来宾介绍：VPM 时间官：May 哼哈官：Jessica 语法官：莫婷 提问官：文星 即兴主持：莫婷 备稿演讲1：卡卡 备稿演讲2：史迪仔 备稿演讲3：[玫瑰] 即兴点评：女侠 备稿点评1：Jessica 备稿点评2：聪聪 备稿点评3：[玫瑰] 总点评：思玮 颁奖&真情分享：卡卡 拍照侠：ALL | D24: @所有人 [烟花]畅言779期报名帖[烟花] 主题：志愿者 今日一词：服务 例会经理：莫婷 时间：6月9日 19:30-21:30 地点: 深圳南山•讯美科技3号楼4楼Space Max会议室 事务官开场：文星 主席致辞：卡卡 总主持：simon 来宾介绍：VPM 时间官：May 哼哈官：Jessica 语法官：莫婷 提问官：文星 即兴主持：莫婷 备稿演讲1：卡卡 备稿演讲2：史迪仔 备稿演讲3：[玫瑰] 即兴点评：女侠 备稿点评1：Jessica 备稿点评2：聪聪 备稿点评3：[玫瑰] 总点评：思玮 颁奖&真情分享：卡卡 拍照侠：ALL | E24: @所有人 [烟花]畅言779期报名帖[烟花] 主题：志愿者 今日一词：服务 例会经理：莫婷 时间：6月9日 19:30-21:30 地点: 深圳南山•讯美科技3号楼4楼Space Max会议室 事务官开场：文星 主席致辞：卡卡 总主持：simon 来宾介绍：VPM 时间官：May 哼哈官：Jessica 语法官：莫婷 提问官：文星 即兴主持：莫婷 备稿演讲1：卡卡 备稿演讲2：史迪仔 备稿演讲3：[玫瑰] 即兴点评：女侠 备稿点评1：Jessica 备稿点评2：聪聪 备稿点评3：[玫瑰] 总点评：思玮 颁奖&真情分享：卡卡 拍照侠：ALL | F24: @所有人 [烟花]畅言779期报名帖[烟花] 主题：志愿者 今日一词：服务 例会经理：莫婷 时间：6月9日 19:30-21:30 地点: 深圳南山•讯美科技3号楼4楼Space Max会议室 事务官开场：文星 主席致辞：卡卡 总主持：simon 来宾介绍：VPM 时间官：May 哼哈官：Jessica 语法官：莫婷 提问官：文星 即兴主持：莫婷 备稿演讲1：卡卡 备稿演讲2：史迪仔 备稿演讲3：[玫瑰] 即兴点评：女侠 备稿点评1：Jessica 备稿点评2：聪聪 备稿点评3：[玫瑰] 总点评：思玮 颁奖&真情分享：卡卡 拍照侠：ALL | G24: @所有人 [烟花]畅言779期报名帖[烟花] 主题：志愿者 今日一词：服务 例会经理：莫婷 时间：6月9日 19:30-21:30 地点: 深圳南山•讯美科技3号楼4楼Space Max会议室 事务官开场：文星 主席致辞：卡卡 总主持：simon 来宾介绍：VPM 时间官：May 哼哈官：Jessica 语法官：莫婷 提问官：文星 即兴主持：莫婷 备稿演讲1：卡卡 备稿演讲2：史迪仔 备稿演讲3：[玫瑰] 即兴点评：女侠 备稿点评1：Jessica 备稿点评2：聪聪 备稿点评3：[玫瑰] 总点评：思玮 颁奖&真情分享：卡卡 拍照侠：ALL | H24: @所有人 [烟花]畅言779期报名帖[烟花] 主题：志愿者 今日一词：服务 例会经理：莫婷 时间：6月9日 19:30-21:30 地点: 深圳南山•讯美科技3号楼4楼Space Max会议室 事务官开场：文星 主席致辞：卡卡 总主持：simon 来宾介绍：VPM 时间官：May 哼哈官：Jessica 语法官：莫婷 提问官：文星 即兴主持：莫婷 备稿演讲1：卡卡 备稿演讲2：史迪仔 备稿演讲3：[玫瑰] 即兴点评：女侠 备稿点评1：Jessica 备稿点评2：聪聪 备稿点评3：[玫瑰] 总点评：思玮 颁奖&真情分享：卡卡 拍照侠：ALL | I24: @所有人 [烟花]畅言779期报名帖[烟花] 主题：志愿者 今日一词：服务 例会经理：莫婷 时间：6月9日 19:30-21:30 地点: 深圳南山•讯美科技3号楼4楼Space Max会议室 事务官开场：文星 主席致辞：卡卡 总主持：simon 来宾介绍：VPM 时间官：May 哼哈官：Jessica 语法官：莫婷 提问官：文星 即兴主持：莫婷 备稿演讲1：卡卡 备稿演讲2：史迪仔 备稿演讲3：[玫瑰] 即兴点评：女侠 备稿点评1：Jessica 备稿点评2：聪聪 备稿点评3：[玫瑰] 总点评：思玮 颁奖&真情分享：卡卡 拍照侠：ALL | J24: @所有人 [烟花]畅言779期报名帖[烟花] 主题：志愿者 今日一词：服务 例会经理：莫婷 时间：6月9日 19:30-21:30 地点: 深圳南山•讯美科技3号楼4楼Space Max会议室 事务官开场：文星 主席致辞：卡卡 总主持：simon 来宾介绍：VPM 时间官：May 哼哈官：Jessica 语法官：莫婷 提问官：文星 即兴主持：莫婷 备稿演讲1：卡卡 备稿演讲2：史迪仔 备稿演讲3：[玫瑰] 即兴点评：女侠 备稿点评1：Jessica 备稿点评2：聪聪 备稿点评3：[玫瑰] 总点评：思玮 颁奖&真情分享：卡卡 拍照侠：ALL | L24: ="解析角色数："&计算区!$E$12&" · 生成项目数："&计算区!$E$13 -> 解析角色数：22 · 生成项目数：21
B25: @所有人 [烟花]畅言779期报名帖[烟花] 主题：志愿者 今日一词：服务 例会经理：莫婷 时间：6月9日 19:30-21:30 地点: 深圳南山•讯美科技3号楼4楼Space Max会议室 事务官开场：文星 主席致辞：卡卡 总主持：simon 来宾介绍：VPM 时间官：May 哼哈官：Jessica 语法官：莫婷 提问官：文星 即兴主持：莫婷 备稿演讲1：卡卡 备稿演讲2：史迪仔 备稿演讲3：[玫瑰] 即兴点评：女侠 备稿点评1：Jessica 备稿点评2：聪聪 备稿点评3：[玫瑰] 总点评：思玮 颁奖&真情分享：卡卡 拍照侠：ALL | C25: @所有人 [烟花]畅言779期报名帖[烟花] 主题：志愿者 今日一词：服务 例会经理：莫婷 时间：6月9日 19:30-21:30 地点: 深圳南山•讯美科技3号楼4楼Space Max会议室 事务官开场：文星 主席致辞：卡卡 总主持：simon 来宾介绍：VPM 时间官：May 哼哈官：Jessica 语法官：莫婷 提问官：文星 即兴主持：莫婷 备稿演讲1：卡卡 备稿演讲2：史迪仔 备稿演讲3：[玫瑰] 即兴点评：女侠 备稿点评1：Jessica 备稿点评2：聪聪 备稿点评3：[玫瑰] 总点评：思玮 颁奖&真情分享：卡卡 拍照侠：ALL | D25: @所有人 [烟花]畅言779期报名帖[烟花] 主题：志愿者 今日一词：服务 例会经理：莫婷 时间：6月9日 19:30-21:30 地点: 深圳南山•讯美科技3号楼4楼Space Max会议室 事务官开场：文星 主席致辞：卡卡 总主持：simon 来宾介绍：VPM 时间官：May 哼哈官：Jessica 语法官：莫婷 提问官：文星 即兴主持：莫婷 备稿演讲1：卡卡 备稿演讲2：史迪仔 备稿演讲3：[玫瑰] 即兴点评：女侠 备稿点评1：Jessica 备稿点评2：聪聪 备稿点评3：[玫瑰] 总点评：思玮 颁奖&真情分享：卡卡 拍照侠：ALL | E25: @所有人 [烟花]畅言779期报名帖[烟花] 主题：志愿者 今日一词：服务 例会经理：莫婷 时间：6月9日 19:30-21:30 地点: 深圳南山•讯美科技3号楼4楼Space Max会议室 事务官开场：文星 主席致辞：卡卡 总主持：simon 来宾介绍：VPM 时间官：May 哼哈官：Jessica 语法官：莫婷 提问官：文星 即兴主持：莫婷 备稿演讲1：卡卡 备稿演讲2：史迪仔 备稿演讲3：[玫瑰] 即兴点评：女侠 备稿点评1：Jessica 备稿点评2：聪聪 备稿点评3：[玫瑰] 总点评：思玮 颁奖&真情分享：卡卡 拍照侠：ALL | F25: @所有人 [烟花]畅言779期报名帖[烟花] 主题：志愿者 今日一词：服务 例会经理：莫婷 时间：6月9日 19:30-21:30 地点: 深圳南山•讯美科技3号楼4楼Space Max会议室 事务官开场：文星 主席致辞：卡卡 总主持：simon 来宾介绍：VPM 时间官：May 哼哈官：Jessica 语法官：莫婷 提问官：文星 即兴主持：莫婷 备稿演讲1：卡卡 备稿演讲2：史迪仔 备稿演讲3：[玫瑰] 即兴点评：女侠 备稿点评1：Jessica 备稿点评2：聪聪 备稿点评3：[玫瑰] 总点评：思玮 颁奖&真情分享：卡卡 拍照侠：ALL | G25: @所有人 [烟花]畅言779期报名帖[烟花] 主题：志愿者 今日一词：服务 例会经理：莫婷 时间：6月9日 19:30-21:30 地点: 深圳南山•讯美科技3号楼4楼Space Max会议室 事务官开场：文星 主席致辞：卡卡 总主持：simon 来宾介绍：VPM 时间官：May 哼哈官：Jessica 语法官：莫婷 提问官：文星 即兴主持：莫婷 备稿演讲1：卡卡 备稿演讲2：史迪仔 备稿演讲3：[玫瑰] 即兴点评：女侠 备稿点评1：Jessica 备稿点评2：聪聪 备稿点评3：[玫瑰] 总点评：思玮 颁奖&真情分享：卡卡 拍照侠：ALL | H25: @所有人 [烟花]畅言779期报名帖[烟花] 主题：志愿者 今日一词：服务 例会经理：莫婷 时间：6月9日 19:30-21:30 地点: 深圳南山•讯美科技3号楼4楼Space Max会议室 事务官开场：文星 主席致辞：卡卡 总主持：simon 来宾介绍：VPM 时间官：May 哼哈官：Jessica 语法官：莫婷 提问官：文星 即兴主持：莫婷 备稿演讲1：卡卡 备稿演讲2：史迪仔 备稿演讲3：[玫瑰] 即兴点评：女侠 备稿点评1：Jessica 备稿点评2：聪聪 备稿点评3：[玫瑰] 总点评：思玮 颁奖&真情分享：卡卡 拍照侠：ALL | I25: @所有人 [烟花]畅言779期报名帖[烟花] 主题：志愿者 今日一词：服务 例会经理：莫婷 时间：6月9日 19:30-21:30 地点: 深圳南山•讯美科技3号楼4楼Space Max会议室 事务官开场：文星 主席致辞：卡卡 总主持：simon 来宾介绍：VPM 时间官：May 哼哈官：Jessica 语法官：莫婷 提问官：文星 即兴主持：莫婷 备稿演讲1：卡卡 备稿演讲2：史迪仔 备稿演讲3：[玫瑰] 即兴点评：女侠 备稿点评1：Jessica 备稿点评2：聪聪 备稿点评3：[玫瑰] 总点评：思玮 颁奖&真情分享：卡卡 拍照侠：ALL | J25: @所有人 [烟花]畅言779期报名帖[烟花] 主题：志愿者 今日一词：服务 例会经理：莫婷 时间：6月9日 19:30-21:30 地点: 深圳南山•讯美科技3号楼4楼Space Max会议室 事务官开场：文星 主席致辞：卡卡 总主持：simon 来宾介绍：VPM 时间官：May 哼哈官：Jessica 语法官：莫婷 提问官：文星 即兴主持：莫婷 备稿演讲1：卡卡 备稿演讲2：史迪仔 备稿演讲3：[玫瑰] 即兴点评：女侠 备稿点评1：Jessica 备稿点评2：聪聪 备稿点评3：[玫瑰] 总点评：思玮 颁奖&真情分享：卡卡 拍照侠：ALL | L25: =IF(计算区!$E$11="","接龙字段已解析；切换来源后生效。",计算区!$E$11) -> 接龙字段已解析；切换来源后生效。
B26: @所有人 [烟花]畅言779期报名帖[烟花] 主题：志愿者 今日一词：服务 例会经理：莫婷 时间：6月9日 19:30-21:30 地点: 深圳南山•讯美科技3号楼4楼Space Max会议室 事务官开场：文星 主席致辞：卡卡 总主持：simon 来宾介绍：VPM 时间官：May 哼哈官：Jessica 语法官：莫婷 提问官：文星 即兴主持：莫婷 备稿演讲1：卡卡 备稿演讲2：史迪仔 备稿演讲3：[玫瑰] 即兴点评：女侠 备稿点评1：Jessica 备稿点评2：聪聪 备稿点评3：[玫瑰] 总点评：思玮 颁奖&真情分享：卡卡 拍照侠：ALL | C26: @所有人 [烟花]畅言779期报名帖[烟花] 主题：志愿者 今日一词：服务 例会经理：莫婷 时间：6月9日 19:30-21:30 地点: 深圳南山•讯美科技3号楼4楼Space Max会议室 事务官开场：文星 主席致辞：卡卡 总主持：simon 来宾介绍：VPM 时间官：May 哼哈官：Jessica 语法官：莫婷 提问官：文星 即兴主持：莫婷 备稿演讲1：卡卡 备稿演讲2：史迪仔 备稿演讲3：[玫瑰] 即兴点评：女侠 备稿点评1：Jessica 备稿点评2：聪聪 备稿点评3：[玫瑰] 总点评：思玮 颁奖&真情分享：卡卡 拍照侠：ALL | D26: @所有人 [烟花]畅言779期报名帖[烟花] 主题：志愿者 今日一词：服务 例会经理：莫婷 时间：6月9日 19:30-21:30 地点: 深圳南山•讯美科技3号楼4楼Space Max会议室 事务官开场：文星 主席致辞：卡卡 总主持：simon 来宾介绍：VPM 时间官：May 哼哈官：Jessica 语法官：莫婷 提问官：文星 即兴主持：莫婷 备稿演讲1：卡卡 备稿演讲2：史迪仔 备稿演讲3：[玫瑰] 即兴点评：女侠 备稿点评1：Jessica 备稿点评2：聪聪 备稿点评3：[玫瑰] 总点评：思玮 颁奖&真情分享：卡卡 拍照侠：ALL | E26: @所有人 [烟花]畅言779期报名帖[烟花] 主题：志愿者 今日一词：服务 例会经理：莫婷 时间：6月9日 19:30-21:30 地点: 深圳南山•讯美科技3号楼4楼Space Max会议室 事务官开场：文星 主席致辞：卡卡 总主持：simon 来宾介绍：VPM 时间官：May 哼哈官：Jessica 语法官：莫婷 提问官：文星 即兴主持：莫婷 备稿演讲1：卡卡 备稿演讲2：史迪仔 备稿演讲3：[玫瑰] 即兴点评：女侠 备稿点评1：Jessica 备稿点评2：聪聪 备稿点评3：[玫瑰] 总点评：思玮 颁奖&真情分享：卡卡 拍照侠：ALL | F26: @所有人 [烟花]畅言779期报名帖[烟花] 主题：志愿者 今日一词：服务 例会经理：莫婷 时间：6月9日 19:30-21:30 地点: 深圳南山•讯美科技3号楼4楼Space Max会议室 事务官开场：文星 主席致辞：卡卡 总主持：simon 来宾介绍：VPM 时间官：May 哼哈官：Jessica 语法官：莫婷 提问官：文星 即兴主持：莫婷 备稿演讲1：卡卡 备稿演讲2：史迪仔 备稿演讲3：[玫瑰] 即兴点评：女侠 备稿点评1：Jessica 备稿点评2：聪聪 备稿点评3：[玫瑰] 总点评：思玮 颁奖&真情分享：卡卡 拍照侠：ALL | G26: @所有人 [烟花]畅言779期报名帖[烟花] 主题：志愿者 今日一词：服务 例会经理：莫婷 时间：6月9日 19:30-21:30 地点: 深圳南山•讯美科技3号楼4楼Space Max会议室 事务官开场：文星 主席致辞：卡卡 总主持：simon 来宾介绍：VPM 时间官：May 哼哈官：Jessica 语法官：莫婷 提问官：文星 即兴主持：莫婷 备稿演讲1：卡卡 备稿演讲2：史迪仔 备稿演讲3：[玫瑰] 即兴点评：女侠 备稿点评1：Jessica 备稿点评2：聪聪 备稿点评3：[玫瑰] 总点评：思玮 颁奖&真情分享：卡卡 拍照侠：ALL | H26: @所有人 [烟花]畅言779期报名帖[烟花] 主题：志愿者 今日一词：服务 例会经理：莫婷 时间：6月9日 19:30-21:30 地点: 深圳南山•讯美科技3号楼4楼Space Max会议室 事务官开场：文星 主席致辞：卡卡 总主持：simon 来宾介绍：VPM 时间官：May 哼哈官：Jessica 语法官：莫婷 提问官：文星 即兴主持：莫婷 备稿演讲1：卡卡 备稿演讲2：史迪仔 备稿演讲3：[玫瑰] 即兴点评：女侠 备稿点评1：Jessica 备稿点评2：聪聪 备稿点评3：[玫瑰] 总点评：思玮 颁奖&真情分享：卡卡 拍照侠：ALL | I26: @所有人 [烟花]畅言779期报名帖[烟花] 主题：志愿者 今日一词：服务 例会经理：莫婷 时间：6月9日 19:30-21:30 地点: 深圳南山•讯美科技3号楼4楼Space Max会议室 事务官开场：文星 主席致辞：卡卡 总主持：simon 来宾介绍：VPM 时间官：May 哼哈官：Jessica 语法官：莫婷 提问官：文星 即兴主持：莫婷 备稿演讲1：卡卡 备稿演讲2：史迪仔 备稿演讲3：[玫瑰] 即兴点评：女侠 备稿点评1：Jessica 备稿点评2：聪聪 备稿点评3：[玫瑰] 总点评：思玮 颁奖&真情分享：卡卡 拍照侠：ALL | J26: @所有人 [烟花]畅言779期报名帖[烟花] 主题：志愿者 今日一词：服务 例会经理：莫婷 时间：6月9日 19:30-21:30 地点: 深圳南山•讯美科技3号楼4楼Space Max会议室 事务官开场：文星 主席致辞：卡卡 总主持：simon 来宾介绍：VPM 时间官：May 哼哈官：Jessica 语法官：莫婷 提问官：文星 即兴主持：莫婷 备稿演讲1：卡卡 备稿演讲2：史迪仔 备稿演讲3：[玫瑰] 即兴点评：女侠 备稿点评1：Jessica 备稿点评2：聪聪 备稿点评3：[玫瑰] 总点评：思玮 颁奖&真情分享：卡卡 拍照侠：ALL | L26: 未识别内容：完整原文保留在左侧；右侧未显示的内容请人工核对。 | M26: 未识别内容：完整原文保留在左侧；右侧未显示的内容请人工核对。 | N26: 未识别内容：完整原文保留在左侧；右侧未显示的内容请人工核对。 | O26: 未识别内容：完整原文保留在左侧；右侧未显示的内容请人工核对。 | P26: 未识别内容：完整原文保留在左侧；右侧未显示的内容请人工核对。
A28: 状态检查 | B28: 状态检查 | C28: 状态检查 | D28: 状态检查 | E28: 状态检查 | F28: 状态检查 | G28: 状态检查 | H28: 状态检查 | I28: 状态检查 | J28: 状态检查 | K28: 状态检查 | L28: 状态检查 | M28: 状态检查 | N28: 状态检查 | O28: 状态检查 | P28: 状态检查
B30: =_xlfn.LET(_xlpm.n,SUM(议程编辑!$S$4:$S$63),_xlpm.bad,计算区!$E$15,_xlpm.missing,计算区!$E$14,_xlpm.overtime,ROUND(计算区!$E$16,0),_xlpm.dateWarning,计算区!$E$11,_xlpm.w,IF(_xlpm.n>60,"议程超过60项，请精简后再打印。"&CHAR(10),"")&IF(_xlpm.n>30,"议程超过单页容量，将使用A4续页。"&CHAR(10),"")&IF(_xlpm.bad>0,"存在缺少或非法排程分钟，后续排程已停止。"&CHAR(10),"")&IF(_xlpm.missing>0,"仍有"&_xlpm.missing&"个负责人待定。"&CHAR(10),"")&IF(_xlpm.overtime>0,"预计超时"&_xlpm.overtime&"分钟。"&CHAR(10),"")&IF(_xlpm.dateWarning<>"",_xlpm.dateWarning,""),IF(_xlpm.w="","议程状态正常，可以检查 A4 成品。",_xlpm.w)) -> 仍有23个负责人待定。
B34: 操作顺序：先选来源 → 检查“议程编辑”黄色修正列 → 查看 A4议程；超过30项时再打印 A4续页。 | C34: 操作顺序：先选来源 → 检查“议程编辑”黄色修正列 → 查看 A4议程；超过30项时再打印 A4续页。 | D34: 操作顺序：先选来源 → 检查“议程编辑”黄色修正列 → 查看 A4议程；超过30项时再打印 A4续页。 | E34: 操作顺序：先选来源 → 检查“议程编辑”黄色修正列 → 查看 A4议程；超过30项时再打印 A4续页。 | F34: 操作顺序：先选来源 → 检查“议程编辑”黄色修正列 → 查看 A4议程；超过30项时再打印 A4续页。 | G34: 操作顺序：先选来源 → 检查“议程编辑”黄色修正列 → 查看 A4议程；超过30项时再打印 A4续页。 | H34: 操作顺序：先选来源 → 检查“议程编辑”黄色修正列 → 查看 A4议程；超过30项时再打印 A4续页。 | I34: 操作顺序：先选来源 → 检查“议程编辑”黄色修正列 → 查看 A4议程；超过30项时再打印 A4续页。 | J34: 操作顺序：先选来源 → 检查“议程编辑”黄色修正列 → 查看 A4议程；超过30项时再打印 A4续页。 | K34: 操作顺序：先选来源 → 检查“议程编辑”黄色修正列 → 查看 A4议程；超过30项时再打印 A4续页。 | L34: 操作顺序：先选来源 → 检查“议程编辑”黄色修正列 → 查看 A4议程；超过30项时再打印 A4续页。 | M34: 操作顺序：先选来源 → 检查“议程编辑”黄色修正列 → 查看 A4议程；超过30项时再打印 A4续页。 | N34: 操作顺序：先选来源 → 检查“议程编辑”黄色修正列 → 查看 A4议程；超过30项时再打印 A4续页。 | O34: 操作顺序：先选来源 → 检查“议程编辑”黄色修正列 → 查看 A4议程；超过30项时再打印 A4续页。 | P34: 操作顺序：先选来源 → 检查“议程编辑”黄色修正列 → 查看 A4议程；超过30项时再打印 A4续页。

Sheet 议程编辑
A1: 议程编辑与手工修正 | B1: 议程编辑与手工修正 | C1: 议程编辑与手工修正 | D1: 议程编辑与手工修正 | E1: 议程编辑与手工修正 | F1: 议程编辑与手工修正 | G1: 议程编辑与手工修正 | H1: 议程编辑与手工修正 | I1: 议程编辑与手工修正 | J1: 议程编辑与手工修正 | K1: 议程编辑与手工修正 | L1: 议程编辑与手工修正 | M1: 议程编辑与手工修正 | N1: 议程编辑与手工修正 | O1: 议程编辑与手工修正 | P1: 议程编辑与手工修正 | Q1: 议程编辑与手工修正 | R1: 辅助
A2: 议程编辑与手工修正 | B2: 议程编辑与手工修正 | C2: 议程编辑与手工修正 | D2: 议程编辑与手工修正 | E2: 议程编辑与手工修正 | F2: 议程编辑与手工修正 | G2: 议程编辑与手工修正 | H2: 议程编辑与手工修正 | I2: 议程编辑与手工修正 | J2: 议程编辑与手工修正 | K2: 议程编辑与手工修正 | L2: 议程编辑与手工修正 | M2: 议程编辑与手工修正 | N2: 议程编辑与手工修正 | O2: 议程编辑与手工修正 | P2: 议程编辑与手工修正 | Q2: 议程编辑与手工修正
A3: 序号 | B3: 项目键 | C3: 分组编号 | D3: 分组名称 | E3: 类型 | F3: 自动开始时间 | G3: 来源标题 | H3: 来源说明 | I3: 来源时长 | J3: 来源排程分钟 | K3: 来源负责人 | L3: 修正标题 | M3: 修正说明 | N3: 修正时长 | O3: 修正排程分钟 | P3: 修正负责人 | Q3: 状态 | R3: 预计结束时间 | S3: 活动行
A4: 1 | B4: {=IF(操作台!$B$4="议程模板",_xlfn.LET(_xlpm.v,IFERROR(INDEX(_xlfn._xlws.FILTER(模板库!$D$2:$D$1000,(模板库!$B$2:$B$1000=操作台!$F$4)*(模板库!$E$2:$E$1000="item")),1),""),IF(OR(_xlpm.v="",_xlpm.v=0),"",_xlpm.v)),IF(操作台!$B$4="接龙导入",IFERROR(INDEX(计算区!$F$5:$F$25,1),""),IF(COUNTA($L4:$P4)>0,"manual-"&TEXT($A4,"00"),"")))} -> i-guest-checkin | C4: {=IF(操作台!$B$4="议程模板",_xlfn.LET(_xlpm.v,IFERROR(INDEX(_xlfn._xlws.FILTER(模板库!$F$2:$F$1000,(模板库!$B$2:$B$1000=操作台!$F$4)*(模板库!$E$2:$E$1000="item")),1),""),IF(OR(_xlpm.v="",_xlpm.v=0),"",_xlpm.v)),IF(操作台!$B$4="接龙导入",IFERROR(INDEX(计算区!$G$5:$G$25,1),""),IF(COUNTA($L4:$P4)>0,1,"")))} -> 1 | D4: {=IF(操作台!$B$4="议程模板",_xlfn.LET(_xlpm.v,IFERROR(INDEX(_xlfn._xlws.FILTER(模板库!$G$2:$G$1000,(模板库!$B$2:$B$1000=操作台!$F$4)*(模板库!$E$2:$E$1000="item")),1),""),IF(OR(_xlpm.v="",_xlpm.v=0),"",_xlpm.v)),IF(操作台!$B$4="接龙导入",IFERROR(INDEX(计算区!$H$5:$H$25,1),""),IF(COUNTA($L4:$P4)>0,"手工议程","")))} -> 开场环节 | E4: {=IF(操作台!$B$4="议程模板",_xlfn.LET(_xlpm.v,IFERROR(INDEX(_xlfn._xlws.FILTER(模板库!$M$2:$M$1000,(模板库!$B$2:$B$1000=操作台!$F$4)*(模板库!$E$2:$E$1000="item")),1),""),IF(OR(_xlpm.v="",_xlpm.v=0),"",_xlpm.v)),IF(操作台!$B$4="接龙导入",IFERROR(INDEX(计算区!$N$5:$N$25,1),""),IF(COUNTA($L4:$P4)>0,"plain","")))} -> plain | F4: =IF($B4="","",IF(操作台!$B$4="接龙导入",IF(计算区!$E$7<>"",计算区!$E$7,操作台!$F$10),操作台!$F$10)) -> 0.80555556 | G4: {=IF(操作台!$B$4="议程模板",_xlfn.LET(_xlpm.v,IFERROR(INDEX(_xlfn._xlws.FILTER(模板库!$H$2:$H$1000,(模板库!$B$2:$B$1000=操作台!$F$4)*(模板库!$E$2:$E$1000="item")),1),""),IF(OR(_xlpm.v="",_xlpm.v=0),"",_xlpm.v)),IF(操作台!$B$4="接龙导入",IFERROR(INDEX(计算区!$I$5:$I$25,1),""),""))} -> 来宾入会，相互认识与交流 | H4: {=IF(操作台!$B$4="议程模板",_xlfn.LET(_xlpm.v,IFERROR(INDEX(_xlfn._xlws.FILTER(模板库!$I$2:$I$1000,(模板库!$B$2:$B$1000=操作台!$F$4)*(模板库!$E$2:$E$1000="item")),1),""),IF(OR(_xlpm.v="",_xlpm.v=0),"",_xlpm.v)),IF(操作台!$B$4="接龙导入","",""))} | I4: {=IF(操作台!$B$4="议程模板",_xlfn.LET(_xlpm.v,IFERROR(INDEX(_xlfn._xlws.FILTER(模板库!$J$2:$J$1000,(模板库!$B$2:$B$1000=操作台!$F$4)*(模板库!$E$2:$E$1000="item")),1),""),IF(OR(_xlpm.v="",_xlpm.v=0),"",_xlpm.v)),IF(操作台!$B$4="接龙导入",IFERROR(INDEX(计算区!$J$5:$J$25,1),""),""))} -> 5 | J4: {=IF(操作台!$B$4="议程模板",_xlfn.LET(_xlpm.v,IFERROR(INDEX(_xlfn._xlws.FILTER(模板库!$K$2:$K$1000,(模板库!$B$2:$B$1000=操作台!$F$4)*(模板库!$E$2:$E$1000="item")),1),""),IF(OR(_xlpm.v="",_xlpm.v=0),"",_xlpm.v)),IF(操作台!$B$4="接龙导入",IFERROR(INDEX(计算区!$K$5:$K$25,1),""),""))} -> 5 | K4: {=IF(操作台!$B$4="议程模板",_xlfn.LET(_xlpm.v,IFERROR(INDEX(_xlfn._xlws.FILTER(模板库!$L$2:$L$1000,(模板库!$B$2:$B$1000=操作台!$F$4)*(模板库!$E$2:$E$1000="item")),1),""),IF(OR(_xlpm.v="",_xlpm.v=0),"",_xlpm.v)),IF(操作台!$B$4="接龙导入",IFERROR(INDEX(计算区!$M$5:$M$25,1),""),""))} -> 全体会员 | Q4: =IF($B4="","",_xlfn.LET(_xlpm.m,IF($O4<>"",$O4,$J4),_xlpm.p,IF($P4<>"",$P4,IF($K4="","待定",$K4)),_xlpm.title,IF($L4<>"",$L4,$G4),_xlfn.TEXTJOIN("；",TRUE,IF(_xlpm.title="","缺少标题",""),IF(_xlpm.m="","缺少排程分钟",IF(NOT(ISNUMBER(_xlpm.m)),"排程分钟无效","")),IF(_xlpm.p="待定","负责人待定",""),IF(AND($A4>1,$F4=""),"前序排程中断","")))) | R4: =IF($B4="","",IF(OR($F4="",IF($O4<>"",NOT(ISNUMBER($O4)),NOT(ISNUMBER($J4)))),"",$F4+IF($O4<>"",$O4,$J4)/1440)) -> 0.80902778 | S4: =IF($B4="",0,1) -> 1
A5: 2 | B5: {=IF(操作台!$B$4="议程模板",_xlfn.LET(_xlpm.v,IFERROR(INDEX(_xlfn._xlws.FILTER(模板库!$D$2:$D$1000,(模板库!$B$2:$B$1000=操作台!$F$4)*(模板库!$E$2:$E$1000="item")),2),""),IF(OR(_xlpm.v="",_xlpm.v=0),"",_xlpm.v)),IF(操作台!$B$4="接龙导入",IFERROR(INDEX(计算区!$F$5:$F$25,2),""),IF(COUNTA($L5:$P5)>0,"manual-"&TEXT($A5,"00"),"")))} -> i-warmup | C5: {=IF(操作台!$B$4="议程模板",_xlfn.LET(_xlpm.v,IFERROR(INDEX(_xlfn._xlws.FILTER(模板库!$F$2:$F$1000,(模板库!$B$2:$B$1000=操作台!$F$4)*(模板库!$E$2:$E$1000="item")),2),""),IF(OR(_xlpm.v="",_xlpm.v=0),"",_xlpm.v)),IF(操作台!$B$4="接龙导入",IFERROR(INDEX(计算区!$G$5:$G$25,2),""),IF(COUNTA($L5:$P5)>0,1,"")))} -> 1 | D5: {=IF(操作台!$B$4="议程模板",_xlfn.LET(_xlpm.v,IFERROR(INDEX(_xlfn._xlws.FILTER(模板库!$G$2:$G$1000,(模板库!$B$2:$B$1000=操作台!$F$4)*(模板库!$E$2:$E$1000="item")),2),""),IF(OR(_xlpm.v="",_xlpm.v=0),"",_xlpm.v)),IF(操作台!$B$4="接龙导入",IFERROR(INDEX(计算区!$H$5:$H$25,2),""),IF(COUNTA($L5:$P5)>0,"手工议程","")))} -> 开场环节 | E5: {=IF(操作台!$B$4="议程模板",_xlfn.LET(_xlpm.v,IFERROR(INDEX(_xlfn._xlws.FILTER(模板库!$M$2:$M$1000,(模板库!$B$2:$B$1000=操作台!$F$4)*(模板库!$E$2:$E$1000="item")),2),""),IF(OR(_xlpm.v="",_xlpm.v=0),"",_xlpm.v)),IF(操作台!$B$4="接龙导入",IFERROR(INDEX(计算区!$N$5:$N$25,2),""),IF(COUNTA($L5:$P5)>0,"plain","")))} -> plain | F5: =IF($B5="","",IF(COUNTIF($Q$4:$Q4,"*排程*")>0,"",IF(COUNTIF($B$4:$B4,"<>")=0,IF(操作台!$B$4="接龙导入",IF(计算区!$E$7<>"",计算区!$E$7,操作台!$F$10),操作台!$F$10),MAX($R$4:$R4)))) -> 0.80902778 | G5: {=IF(操作台!$B$4="议程模板",_xlfn.LET(_xlpm.v,IFERROR(INDEX(_xlfn._xlws.FILTER(模板库!$H$2:$H$1000,(模板库!$B$2:$B$1000=操作台!$F$4)*(模板库!$E$2:$E$1000="item")),2),""),IF(OR(_xlpm.v="",_xlpm.v=0),"",_xlpm.v)),IF(操作台!$B$4="接龙导入",IFERROR(INDEX(计算区!$I$5:$I$25,2),""),""))} -> 暖场互动 | H5: {=IF(操作台!$B$4="议程模板",_xlfn.LET(_xlpm.v,IFERROR(INDEX(_xlfn._xlws.FILTER(模板库!$I$2:$I$1000,(模板库!$B$2:$B$1000=操作台!$F$4)*(模板库!$E$2:$E$1000="item")),2),""),IF(OR(_xlpm.v="",_xlpm.v=0),"",_xlpm.v)),IF(操作台!$B$4="接龙导入","",""))} | I5: {=IF(操作台!$B$4="议程模板",_xlfn.LET(_xlpm.v,IFERROR(INDEX(_xlfn._xlws.FILTER(模板库!$J$2:$J$1000,(模板库!$B$2:$B$1000=操作台!$F$4)*(模板库!$E$2:$E$1000="item")),2),""),IF(OR(_xlpm.v="",_xlpm.v=0),"",_xlpm.v)),IF(操作台!$B$4="接龙导入",IFERROR(INDEX(计算区!$J$5:$J$25,2),""),""))} -> 5 | J5: {=IF(操作台!$B$4="议程模板",_xlfn.LET(_xlpm.v,IFERROR(INDEX(_xlfn._xlws.FILTER(模板库!$K$2:$K$1000,(模板库!$B$2:$B$1000=操作台!$F$4)*(模板库!$E$2:$E$1000="item")),2),""),IF(OR(_xlpm.v="",_xlpm.v=0),"",_xlpm.v)),IF(操作台!$B$4="接龙导入",IFERROR(INDEX(计算区!$K$5:$K$25,2),""),""))} -> 5 | K5: {=IF(操作台!$B$4="议程模板",_xlfn.LET(_xlpm.v,IFERROR(INDEX(_xlfn._xlws.FILTER(模板库!$L$2:$L$1000,(模板库!$B$2:$B$1000=操作台!$F$4)*(模板库!$E$2:$E$1000="item")),2),""),IF(OR(_xlpm.v="",_xlpm.v=0),"",_xlpm.v)),IF(操作台!$B$4="接龙导入",IFERROR(INDEX(计算区!$M$5:$M$25,2),""),""))} -> 全体会员 | Q5: =IF($B5="","",_xlfn.LET(_xlpm.m,IF($O5<>"",$O5,$J5),_xlpm.p,IF($P5<>"",$P5,IF($K5="","待定",$K5)),_xlpm.title,IF($L5<>"",$L5,$G5),_xlfn.TEXTJOIN("；",TRUE,IF(_xlpm.title="","缺少标题",""),IF(_xlpm.m="","缺少排程分钟",IF(NOT(ISNUMBER(_xlpm.m)),"排程分钟无效","")),IF(_xlpm.p="待定","负责人待定",""),IF(AND($A5>1,$F5=""),"前序排程中断","")))) | R5: =IF($B5="","",IF(OR($F5="",IF($O5<>"",NOT(ISNUMBER($O5)),NOT(ISNUMBER($J5)))),"",$F5+IF($O5<>"",$O5,$J5)/1440)) -> 0.8125 | S5: =IF($B5="",0,1) -> 1
A6: 3 | B6: {=IF(操作台!$B$4="议程模板",_xlfn.LET(_xlpm.v,IFERROR(INDEX(_xlfn._xlws.FILTER(模板库!$D$2:$D$1000,(模板库!$B$2:$B$1000=操作台!$F$4)*(模板库!$E$2:$E$1000="item")),3),""),IF(OR(_xlpm.v="",_xlpm.v=0),"",_xlpm.v)),IF(操作台!$B$4="接龙导入",IFERROR(INDEX(计算区!$F$5:$F$25,3),""),IF(COUNTA($L6:$P6)>0,"manual-"&TEXT($A6,"00"),"")))} -> i-rules | C6: {=IF(操作台!$B$4="议程模板",_xlfn.LET(_xlpm.v,IFERROR(INDEX(_xlfn._xlws.FILTER(模板库!$F$2:$F$1000,(模板库!$B$2:$B$1000=操作台!$F$4)*(模板库!$E$2:$E$1000="item")),3),""),IF(OR(_xlpm.v="",_xlpm.v=0),"",_xlpm.v)),IF(操作台!$B$4="接龙导入",IFERROR(INDEX(计算区!$G$5:$G$25,3),""),IF(COUNTA($L6:$P6)>0,1,"")))} -> 1 | D6: {=IF(操作台!$B$4="议程模板",_xlfn.LET(_xlpm.v,IFERROR(INDEX(_xlfn._xlws.FILTER(模板库!$G$2:$G$1000,(模板库!$B$2:$B$1000=操作台!$F$4)*(模板库!$E$2:$E$1000="item")),3),""),IF(OR(_xlpm.v="",_xlpm.v=0),"",_xlpm.v)),IF(操作台!$B$4="接龙导入",IFERROR(INDEX(计算区!$H$5:$H$25,3),""),IF(COUNTA($L6:$P6)>0,"手工议程","")))} -> 开场环节 | E6: {=IF(操作台!$B$4="议程模板",_xlfn.LET(_xlpm.v,IFERROR(INDEX(_xlfn._xlws.FILTER(模板库!$M$2:$M$1000,(模板库!$B$2:$B$1000=操作台!$F$4)*(模板库!$E$2:$E$1000="item")),3),""),IF(OR(_xlpm.v="",_xlpm.v=0),"",_xlpm.v)),IF(操作台!$B$4="接龙导入",IFERROR(INDEX(计算区!$N$5:$N$25,3),""),IF(COUNTA($L6:$P6)>0,"plain","")))} -> plain | F6: =IF($B6="","",IF(COUNTIF($Q$4:$Q5,"*排程*")>0,"",IF(COUNTIF($B$4:$B5,"<>")=0,IF(操作台!$B$4="接龙导入",IF(计算区!$E$7<>"",计算区!$E$7,操作台!$F$10),操作台!$F$10),MAX($R$4:$R5)))) -> 0.8125 | G6: {=IF(操作台!$B$4="议程模板",_xlfn.LET(_xlpm.v,IFERROR(INDEX(_xlfn._xlws.FILTER(模板库!$H$2:$H$1000,(模板库!$B$2:$B$1000=操作台!$F$4)*(模板库!$E$2:$E$1000="item")),3),""),IF(OR(_xlpm.v="",_xlpm.v=0),"",_xlpm.v)),IF(操作台!$B$4="接龙导入",IFERROR(INDEX(计算区!$I$5:$I$25,3),""),""))} -> 事务官宣布会议规则 | H6: {=IF(操作台!$B$4="议程模板",_xlfn.LET(_xlpm.v,IFERROR(INDEX(_xlfn._xlws.FILTER(模板库!$I$2:$I$1000,(模板库!$B$2:$B$1000=操作台!$F$4)*(模板库!$E$2:$E$1000="item")),3),""),IF(OR(_xlpm.v="",_xlpm.v=0),"",_xlpm.v)),IF(操作台!$B$4="接龙导入","",""))} | I6: {=IF(操作台!$B$4="议程模板",_xlfn.LET(_xlpm.v,IFERROR(INDEX(_xlfn._xlws.FILTER(模板库!$J$2:$J$1000,(模板库!$B$2:$B$1000=操作台!$F$4)*(模板库!$E$2:$E$1000="item")),3),""),IF(OR(_xlpm.v="",_xlpm.v=0),"",_xlpm.v)),IF(操作台!$B$4="接龙导入",IFERROR(INDEX(计算区!$J$5:$J$25,3),""),""))} -> 1 | J6: {=IF(操作台!$B$4="议程模板",_xlfn.LET(_xlpm.v,IFERROR(INDEX(_xlfn._xlws.FILTER(模板库!$K$2:$K$1000,(模板库!$B$2:$B$1000=操作台!$F$4)*(模板库!$E$2:$E$1000="item")),3),""),IF(OR(_xlpm.v="",_xlpm.v=0),"",_xlpm.v)),IF(操作台!$B$4="接龙导入",IFERROR(INDEX(计算区!$K$5:$K$25,3),""),""))} -> 1 | K6: {=IF(操作台!$B$4="议程模板",_xlfn.LET(_xlpm.v,IFERROR(INDEX(_xlfn._xlws.FILTER(模板库!$L$2:$L$1000,(模板库!$B$2:$B$1000=操作台!$F$4)*(模板库!$E$2:$E$1000="item")),3),""),IF(OR(_xlpm.v="",_xlpm.v=0),"",_xlpm.v)),IF(操作台!$B$4="接龙导入",IFERROR(INDEX(计算区!$M$5:$M$25,3),""),""))} | Q6: =IF($B6="","",_xlfn.LET(_xlpm.m,IF($O6<>"",$O6,$J6),_xlpm.p,IF($P6<>"",$P6,IF($K6="","待定",$K6)),_xlpm.title,IF($L6<>"",$L6,$G6),_xlfn.TEXTJOIN("；",TRUE,IF(_xlpm.title="","缺少标题",""),IF(_xlpm.m="","缺少排程分钟",IF(NOT(ISNUMBER(_xlpm.m)),"排程分钟无效","")),IF(_xlpm.p="待定","负责人待定",""),IF(AND($A6>1,$F6=""),"前序排程中断","")))) -> 负责人待定 | R6: =IF($B6="","",IF(OR($F6="",IF($O6<>"",NOT(ISNUMBER($O6)),NOT(ISNUMBER($J6)))),"",$F6+IF($O6<>"",$O6,$J6)/1440)) -> 0.81319444 | S6: =IF($B6="",0,1) -> 1
A7: 4 | B7: {=IF(操作台!$B$4="议程模板",_xlfn.LET(_xlpm.v,IFERROR(INDEX(_xlfn._xlws.FILTER(模板库!$D$2:$D$1000,(模板库!$B$2:$B$1000=操作台!$F$4)*(模板库!$E$2:$E$1000="item")),4),""),IF(OR(_xlpm.v="",_xlpm.v=0),"",_xlpm.v)),IF(操作台!$B$4="接龙导入",IFERROR(INDEX(计算区!$F$5:$F$25,4),""),IF(COUNTA($L7:$P7)>0,"manual-"&TEXT($A7,"00"),"")))} -> i-president | C7: {=IF(操作台!$B$4="议程模板",_xlfn.LET(_xlpm.v,IFERROR(INDEX(_xlfn._xlws.FILTER(模板库!$F$2:$F$1000,(模板库!$B$2:$B$1000=操作台!$F$4)*(模板库!$E$2:$E$1000="item")),4),""),IF(OR(_xlpm.v="",_xlpm.v=0),"",_xlpm.v)),IF(操作台!$B$4="接龙导入",IFERROR(INDEX(计算区!$G$5:$G$25,4),""),IF(COUNTA($L7:$P7)>0,1,"")))} -> 1 | D7: {=IF(操作台!$B$4="议程模板",_xlfn.LET(_xlpm.v,IFERROR(INDEX(_xlfn._xlws.FILTER(模板库!$G$2:$G$1000,(模板库!$B$2:$B$1000=操作台!$F$4)*(模板库!$E$2:$E$1000="item")),4),""),IF(OR(_xlpm.v="",_xlpm.v=0),"",_xlpm.v)),IF(操作台!$B$4="接龙导入",IFERROR(INDEX(计算区!$H$5:$H$25,4),""),IF(COUNTA($L7:$P7)>0,"手工议程","")))} -> 开场环节 | E7: {=IF(操作台!$B$4="议程模板",_xlfn.LET(_xlpm.v,IFERROR(INDEX(_xlfn._xlws.FILTER(模板库!$M$2:$M$1000,(模板库!$B$2:$B$1000=操作台!$F$4)*(模板库!$E$2:$E$1000="item")),4),""),IF(OR(_xlpm.v="",_xlpm.v=0),"",_xlpm.v)),IF(操作台!$B$4="接龙导入",IFERROR(INDEX(计算区!$N$5:$N$25,4),""),IF(COUNTA($L7:$P7)>0,"plain","")))} -> plain | F7: =IF($B7="","",IF(COUNTIF($Q$4:$Q6,"*排程*")>0,"",IF(COUNTIF($B$4:$B6,"<>")=0,IF(操作台!$B$4="接龙导入",IF(计算区!$E$7<>"",计算区!$E$7,操作台!$F$10),操作台!$F$10),MAX($R$4:$R6)))) -> 0.81319444 | G7: {=IF(操作台!$B$4="议程模板",_xlfn.LET(_xlpm.v,IFERROR(INDEX(_xlfn._xlws.FILTER(模板库!$H$2:$H$1000,(模板库!$B$2:$B$1000=操作台!$F$4)*(模板库!$E$2:$E$1000="item")),4),""),IF(OR(_xlpm.v="",_xlpm.v=0),"",_xlpm.v)),IF(操作台!$B$4="接龙导入",IFERROR(INDEX(计算区!$I$5:$I$25,4),""),""))} -> 主席致词 | H7: {=IF(操作台!$B$4="议程模板",_xlfn.LET(_xlpm.v,IFERROR(INDEX(_xlfn._xlws.FILTER(模板库!$I$2:$I$1000,(模板库!$B$2:$B$1000=操作台!$F$4)*(模板库!$E$2:$E$1000="item")),4),""),IF(OR(_xlpm.v="",_xlpm.v=0),"",_xlpm.v)),IF(操作台!$B$4="接龙导入","",""))} | I7: {=IF(操作台!$B$4="议程模板",_xlfn.LET(_xlpm.v,IFERROR(INDEX(_xlfn._xlws.FILTER(模板库!$J$2:$J$1000,(模板库!$B$2:$B$1000=操作台!$F$4)*(模板库!$E$2:$E$1000="item")),4),""),IF(OR(_xlpm.v="",_xlpm.v=0),"",_xlpm.v)),IF(操作台!$B$4="接龙导入",IFERROR(INDEX(计算区!$J$5:$J$25,4),""),""))} -> 3 | J7: {=IF(操作台!$B$4="议程模板",_xlfn.LET(_xlpm.v,IFERROR(INDEX(_xlfn._xlws.FILTER(模板库!$K$2:$K$1000,(模板库!$B$2:$B$1000=操作台!$F$4)*(模板库!$E$2:$E$1000="item")),4),""),IF(OR(_xlpm.v="",_xlpm.v=0),"",_xlpm.v)),IF(操作台!$B$4="接龙导入",IFERROR(INDEX(计算区!$K$5:$K$25,4),""),""))} -> 3 | K7: {=IF(操作台!$B$4="议程模板",_xlfn.LET(_xlpm.v,IFERROR(INDEX(_xlfn._xlws.FILTER(模板库!$L$2:$L$1000,(模板库!$B$2:$B$1000=操作台!$F$4)*(模板库!$E$2:$E$1000="item")),4),""),IF(OR(_xlpm.v="",_xlpm.v=0),"",_xlpm.v)),IF(操作台!$B$4="接龙导入",IFERROR(INDEX(计算区!$M$5:$M$25,4),""),""))} | Q7: =IF($B7="","",_xlfn.LET(_xlpm.m,IF($O7<>"",$O7,$J7),_xlpm.p,IF($P7<>"",$P7,IF($K7="","待定",$K7)),_xlpm.title,IF($L7<>"",$L7,$G7),_xlfn.TEXTJOIN("；",TRUE,IF(_xlpm.title="","缺少标题",""),IF(_xlpm.m="","缺少排程分钟",IF(NOT(ISNUMBER(_xlpm.m)),"排程分钟无效","")),IF(_xlpm.p="待定","负责人待定",""),IF(AND($A7>1,$F7=""),"前序排程中断","")))) -> 负责人待定 | R7: =IF($B7="","",IF(OR($F7="",IF($O7<>"",NOT(ISNUMBER($O7)),NOT(ISNUMBER($J7)))),"",$F7+IF($O7<>"",$O7,$J7)/1440)) -> 0.81527778 | S7: =IF($B7="",0,1) -> 1
A8: 5 | B8: {=IF(操作台!$B$4="议程模板",_xlfn.LET(_xlpm.v,IFERROR(INDEX(_xlfn._xlws.FILTER(模板库!$D$2:$D$1000,(模板库!$B$2:$B$1000=操作台!$F$4)*(模板库!$E$2:$E$1000="item")),5),""),IF(OR(_xlpm.v="",_xlpm.v=0),"",_xlpm.v)),IF(操作台!$B$4="接龙导入",IFERROR(INDEX(计算区!$F$5:$F$25,5),""),IF(COUNTA($L8:$P8)>0,"manual-"&TEXT($A8,"00"),"")))} -> i-host-open | C8: {=IF(操作台!$B$4="议程模板",_xlfn.LET(_xlpm.v,IFERROR(INDEX(_xlfn._xlws.FILTER(模板库!$F$2:$F$1000,(模板库!$B$2:$B$1000=操作台!$F$4)*(模板库!$E$2:$E$1000="item")),5),""),IF(OR(_xlpm.v="",_xlpm.v=0),"",_xlpm.v)),IF(操作台!$B$4="接龙导入",IFERROR(INDEX(计算区!$G$5:$G$25,5),""),IF(COUNTA($L8:$P8)>0,1,"")))} -> 1 | D8: {=IF(操作台!$B$4="议程模板",_xlfn.LET(_xlpm.v,IFERROR(INDEX(_xlfn._xlws.FILTER(模板库!$G$2:$G$1000,(模板库!$B$2:$B$1000=操作台!$F$4)*(模板库!$E$2:$E$1000="item")),5),""),IF(OR(_xlpm.v="",_xlpm.v=0),"",_xlpm.v)),IF(操作台!$B$4="接龙导入",IFERROR(INDEX(计算区!$H$5:$H$25,5),""),IF(COUNTA($L8:$P8)>0,"手工议程","")))} -> 开场环节 | E8: {=IF(操作台!$B$4="议程模板",_xlfn.LET(_xlpm.v,IFERROR(INDEX(_xlfn._xlws.FILTER(模板库!$M$2:$M$1000,(模板库!$B$2:$B$1000=操作台!$F$4)*(模板库!$E$2:$E$1000="item")),5),""),IF(OR(_xlpm.v="",_xlpm.v=0),"",_xlpm.v)),IF(操作台!$B$4="接龙导入",IFERROR(INDEX(计算区!$N$5:$N$25,5),""),IF(COUNTA($L8:$P8)>0,"plain","")))} -> plain | F8: =IF($B8="","",IF(COUNTIF($Q$4:$Q7,"*排程*")>0,"",IF(COUNTIF($B$4:$B7,"<>")=0,IF(操作台!$B$4="接龙导入",IF(计算区!$E$7<>"",计算区!$E$7,操作台!$F$10),操作台!$F$10),MAX($R$4:$R7)))) -> 0.81527778 | G8: {=IF(操作台!$B$4="议程模板",_xlfn.LET(_xlpm.v,IFERROR(INDEX(_xlfn._xlws.FILTER(模板库!$H$2:$H$1000,(模板库!$B$2:$B$1000=操作台!$F$4)*(模板库!$E$2:$E$1000="item")),5),""),IF(OR(_xlpm.v="",_xlpm.v=0),"",_xlpm.v)),IF(操作台!$B$4="接龙导入",IFERROR(INDEX(计算区!$I$5:$I$25,5),""),""))} -> 总主持开场，介绍会议流程 | H8: {=IF(操作台!$B$4="议程模板",_xlfn.LET(_xlpm.v,IFERROR(INDEX(_xlfn._xlws.FILTER(模板库!$I$2:$I$1000,(模板库!$B$2:$B$1000=操作台!$F$4)*(模板库!$E$2:$E$1000="item")),5),""),IF(OR(_xlpm.v="",_xlpm.v=0),"",_xlpm.v)),IF(操作台!$B$4="接龙导入","",""))} | I8: {=IF(操作台!$B$4="议程模板",_xlfn.LET(_xlpm.v,IFERROR(INDEX(_xlfn._xlws.FILTER(模板库!$J$2:$J$1000,(模板库!$B$2:$B$1000=操作台!$F$4)*(模板库!$E$2:$E$1000="item")),5),""),IF(OR(_xlpm.v="",_xlpm.v=0),"",_xlpm.v)),IF(操作台!$B$4="接龙导入",IFERROR(INDEX(计算区!$J$5:$J$25,5),""),""))} -> 2 | J8: {=IF(操作台!$B$4="议程模板",_xlfn.LET(_xlpm.v,IFERROR(INDEX(_xlfn._xlws.FILTER(模板库!$K$2:$K$1000,(模板库!$B$2:$B$1000=操作台!$F$4)*(模板库!$E$2:$E$1000="item")),5),""),IF(OR(_xlpm.v="",_xlpm.v=0),"",_xlpm.v)),IF(操作台!$B$4="接龙导入",IFERROR(INDEX(计算区!$K$5:$K$25,5),""),""))} -> 2 | K8: {=IF(操作台!$B$4="议程模板",_xlfn.LET(_xlpm.v,IFERROR(INDEX(_xlfn._xlws.FILTER(模板库!$L$2:$L$1000,(模板库!$B$2:$B$1000=操作台!$F$4)*(模板库!$E$2:$E$1000="item")),5),""),IF(OR(_xlpm.v="",_xlpm.v=0),"",_xlpm.v)),IF(操作台!$B$4="接龙导入",IFERROR(INDEX(计算区!$M$5:$M$25,5),""),""))} | Q8: =IF($B8="","",_xlfn.LET(_xlpm.m,IF($O8<>"",$O8,$J8),_xlpm.p,IF($P8<>"",$P8,IF($K8="","待定",$K8)),_xlpm.title,IF($L8<>"",$L8,$G8),_xlfn.TEXTJOIN("；",TRUE,IF(_xlpm.title="","缺少标题",""),IF(_xlpm.m="","缺少排程分钟",IF(NOT(ISNUMBER(_xlpm.m)),"排程分钟无效","")),IF(_xlpm.p="待定","负责人待定",""),IF(AND($A8>1,$F8=""),"前序排程中断","")))) -> 负责人待定 | R8: =IF($B8="","",IF(OR($F8="",IF($O8<>"",NOT(ISNUMBER($O8)),NOT(ISNUMBER($J8)))),"",$F8+IF($O8<>"",$O8,$J8)/1440)) -> 0.81666667 | S8: =IF($B8="",0,1) -> 1
A9: 6 | B9: {=IF(操作台!$B$4="议程模板",_xlfn.LET(_xlpm.v,IFERROR(INDEX(_xlfn._xlws.FILTER(模板库!$D$2:$D$1000,(模板库!$B$2:$B$1000=操作台!$F$4)*(模板库!$E$2:$E$1000="item")),6),""),IF(OR(_xlpm.v="",_xlpm.v=0),"",_xlpm.v)),IF(操作台!$B$4="接龙导入",IFERROR(INDEX(计算区!$F$5:$F$25,6),""),IF(COUNTA($L9:$P9)>0,"manual-"&TEXT($A9,"00"),"")))} -> i-timer-declare | C9: {=IF(操作台!$B$4="议程模板",_xlfn.LET(_xlpm.v,IFERROR(INDEX(_xlfn._xlws.FILTER(模板库!$F$2:$F$1000,(模板库!$B$2:$B$1000=操作台!$F$4)*(模板库!$E$2:$E$1000="item")),6),""),IF(OR(_xlpm.v="",_xlpm.v=0),"",_xlpm.v)),IF(操作台!$B$4="接龙导入",IFERROR(INDEX(计算区!$G$5:$G$25,6),""),IF(COUNTA($L9:$P9)>0,1,"")))} -> 1 | D9: {=IF(操作台!$B$4="议程模板",_xlfn.LET(_xlpm.v,IFERROR(INDEX(_xlfn._xlws.FILTER(模板库!$G$2:$G$1000,(模板库!$B$2:$B$1000=操作台!$F$4)*(模板库!$E$2:$E$1000="item")),6),""),IF(OR(_xlpm.v="",_xlpm.v=0),"",_xlpm.v)),IF(操作台!$B$4="接龙导入",IFERROR(INDEX(计算区!$H$5:$H$25,6),""),IF(COUNTA($L9:$P9)>0,"手工议程","")))} -> 开场环节 | E9: {=IF(操作台!$B$4="议程模板",_xlfn.LET(_xlpm.v,IFERROR(INDEX(_xlfn._xlws.FILTER(模板库!$M$2:$M$1000,(模板库!$B$2:$B$1000=操作台!$F$4)*(模板库!$E$2:$E$1000="item")),6),""),IF(OR(_xlpm.v="",_xlpm.v=0),"",_xlpm.v)),IF(操作台!$B$4="接龙导入",IFERROR(INDEX(计算区!$N$5:$N$25,6),""),IF(COUNTA($L9:$P9)>0,"plain","")))} -> plain | F9: =IF($B9="","",IF(COUNTIF($Q$4:$Q8,"*排程*")>0,"",IF(COUNTIF($B$4:$B8,"<>")=0,IF(操作台!$B$4="接龙导入",IF(计算区!$E$7<>"",计算区!$E$7,操作台!$F$10),操作台!$F$10),MAX($R$4:$R8)))) -> 0.81666667 | G9: {=IF(操作台!$B$4="议程模板",_xlfn.LET(_xlpm.v,IFERROR(INDEX(_xlfn._xlws.FILTER(模板库!$H$2:$H$1000,(模板库!$B$2:$B$1000=操作台!$F$4)*(模板库!$E$2:$E$1000="item")),6),""),IF(OR(_xlpm.v="",_xlpm.v=0),"",_xlpm.v)),IF(操作台!$B$4="接龙导入",IFERROR(INDEX(计算区!$I$5:$I$25,6),""),""))} -> 时间官宣言 | H9: {=IF(操作台!$B$4="议程模板",_xlfn.LET(_xlpm.v,IFERROR(INDEX(_xlfn._xlws.FILTER(模板库!$I$2:$I$1000,(模板库!$B$2:$B$1000=操作台!$F$4)*(模板库!$E$2:$E$1000="item")),6),""),IF(OR(_xlpm.v="",_xlpm.v=0),"",_xlpm.v)),IF(操作台!$B$4="接龙导入","",""))} | I9: {=IF(操作台!$B$4="议程模板",_xlfn.LET(_xlpm.v,IFERROR(INDEX(_xlfn._xlws.FILTER(模板库!$J$2:$J$1000,(模板库!$B$2:$B$1000=操作台!$F$4)*(模板库!$E$2:$E$1000="item")),6),""),IF(OR(_xlpm.v="",_xlpm.v=0),"",_xlpm.v)),IF(操作台!$B$4="接龙导入",IFERROR(INDEX(计算区!$J$5:$J$25,6),""),""))} -> 2 | J9: {=IF(操作台!$B$4="议程模板",_xlfn.LET(_xlpm.v,IFERROR(INDEX(_xlfn._xlws.FILTER(模板库!$K$2:$K$1000,(模板库!$B$2:$B$1000=操作台!$F$4)*(模板库!$E$2:$E$1000="item")),6),""),IF(OR(_xlpm.v="",_xlpm.v=0),"",_xlpm.v)),IF(操作台!$B$4="接龙导入",IFERROR(INDEX(计算区!$K$5:$K$25,6),""),""))} -> 2 | K9: {=IF(操作台!$B$4="议程模板",_xlfn.LET(_xlpm.v,IFERROR(INDEX(_xlfn._xlws.FILTER(模板库!$L$2:$L$1000,(模板库!$B$2:$B$1000=操作台!$F$4)*(模板库!$E$2:$E$1000="item")),6),""),IF(OR(_xlpm.v="",_xlpm.v=0),"",_xlpm.v)),IF(操作台!$B$4="接龙导入",IFERROR(INDEX(计算区!$M$5:$M$25,6),""),""))} | Q9: =IF($B9="","",_xlfn.LET(_xlpm.m,IF($O9<>"",$O9,$J9),_xlpm.p,IF($P9<>"",$P9,IF($K9="","待定",$K9)),_xlpm.title,IF($L9<>"",$L9,$G9),_xlfn.TEXTJOIN("；",TRUE,IF(_xlpm.title="","缺少标题",""),IF(_xlpm.m="","缺少排程分钟",IF(NOT(ISNUMBER(_xlpm.m)),"排程分钟无效","")),IF(_xlpm.p="待定","负责人待定",""),IF(AND($A9>1,$F9=""),"前序排程中断","")))) -> 负责人待定 | R9: =IF($B9="","",IF(OR($F9="",IF($O9<>"",NOT(ISNUMBER($O9)),NOT(ISNUMBER($J9)))),"",$F9+IF($O9<>"",$O9,$J9)/1440)) -> 0.81805556 | S9: =IF($B9="",0,1) -> 1
A10: 7 | B10: {=IF(操作台!$B$4="议程模板",_xlfn.LET(_xlpm.v,IFERROR(INDEX(_xlfn._xlws.FILTER(模板库!$D$2:$D$1000,(模板库!$B$2:$B$1000=操作台!$F$4)*(模板库!$E$2:$E$1000="item")),7),""),IF(OR(_xlpm.v="",_xlpm.v=0),"",_xlpm.v)),IF(操作台!$B$4="接龙导入",IFERROR(INDEX(计算区!$F$5:$F$25,7),""),IF(COUNTA($L10:$P10)>0,"manual-"&TEXT($A10,"00"),"")))} -> i-ah-declare | C10: {=IF(操作台!$B$4="议程模板",_xlfn.LET(_xlpm.v,IFERROR(INDEX(_xlfn._xlws.FILTER(模板库!$F$2:$F$1000,(模板库!$B$2:$B$1000=操作台!$F$4)*(模板库!$E$2:$E$1000="item")),7),""),IF(OR(_xlpm.v="",_xlpm.v=0),"",_xlpm.v)),IF(操作台!$B$4="接龙导入",IFERROR(INDEX(计算区!$G$5:$G$25,7),""),IF(COUNTA($L10:$P10)>0,1,"")))} -> 1 | D10: {=IF(操作台!$B$4="议程模板",_xlfn.LET(_xlpm.v,IFERROR(INDEX(_xlfn._xlws.FILTER(模板库!$G$2:$G$1000,(模板库!$B$2:$B$1000=操作台!$F$4)*(模板库!$E$2:$E$1000="item")),7),""),IF(OR(_xlpm.v="",_xlpm.v=0),"",_xlpm.v)),IF(操作台!$B$4="接龙导入",IFERROR(INDEX(计算区!$H$5:$H$25,7),""),IF(COUNTA($L10:$P10)>0,"手工议程","")))} -> 开场环节 | E10: {=IF(操作台!$B$4="议程模板",_xlfn.LET(_xlpm.v,IFERROR(INDEX(_xlfn._xlws.FILTER(模板库!$M$2:$M$1000,(模板库!$B$2:$B$1000=操作台!$F$4)*(模板库!$E$2:$E$1000="item")),7),""),IF(OR(_xlpm.v="",_xlpm.v=0),"",_xlpm.v)),IF(操作台!$B$4="接龙导入",IFERROR(INDEX(计算区!$N$5:$N$25,7),""),IF(COUNTA($L10:$P10)>0,"plain","")))} -> plain | F10: =IF($B10="","",IF(COUNTIF($Q$4:$Q9,"*排程*")>0,"",IF(COUNTIF($B$4:$B9,"<>")=0,IF(操作台!$B$4="接龙导入",IF(计算区!$E$7<>"",计算区!$E$7,操作台!$F$10),操作台!$F$10),MAX($R$4:$R9)))) -> 0.81805556 | G10: {=IF(操作台!$B$4="议程模板",_xlfn.LET(_xlpm.v,IFERROR(INDEX(_xlfn._xlws.FILTER(模板库!$H$2:$H$1000,(模板库!$B$2:$B$1000=操作台!$F$4)*(模板库!$E$2:$E$1000="item")),7),""),IF(OR(_xlpm.v="",_xlpm.v=0),"",_xlpm.v)),IF(操作台!$B$4="接龙导入",IFERROR(INDEX(计算区!$I$5:$I$25,7),""),""))} -> 哼哈官宣言 | H10: {=IF(操作台!$B$4="议程模板",_xlfn.LET(_xlpm.v,IFERROR(INDEX(_xlfn._xlws.FILTER(模板库!$I$2:$I$1000,(模板库!$B$2:$B$1000=操作台!$F$4)*(模板库!$E$2:$E$1000="item")),7),""),IF(OR(_xlpm.v="",_xlpm.v=0),"",_xlpm.v)),IF(操作台!$B$4="接龙导入","",""))} | I10: {=IF(操作台!$B$4="议程模板",_xlfn.LET(_xlpm.v,IFERROR(INDEX(_xlfn._xlws.FILTER(模板库!$J$2:$J$1000,(模板库!$B$2:$B$1000=操作台!$F$4)*(模板库!$E$2:$E$1000="item")),7),""),IF(OR(_xlpm.v="",_xlpm.v=0),"",_xlpm.v)),IF(操作台!$B$4="接龙导入",IFERROR(INDEX(计算区!$J$5:$J$25,7),""),""))} -> 2 | J10: {=IF(操作台!$B$4="议程模板",_xlfn.LET(_xlpm.v,IFERROR(INDEX(_xlfn._xlws.FILTER(模板库!$K$2:$K$1000,(模板库!$B$2:$B$1000=操作台!$F$4)*(模板库!$E$2:$E$1000="item")),7),""),IF(OR(_xlpm.v="",_xlpm.v=0),"",_xlpm.v)),IF(操作台!$B$4="接龙导入",IFERROR(INDEX(计算区!$K$5:$K$25,7),""),""))} -> 2 | K10: {=IF(操作台!$B$4="议程模板",_xlfn.LET(_xlpm.v,IFERROR(INDEX(_xlfn._xlws.FILTER(模板库!$L$2:$L$1000,(模板库!$B$2:$B$1000=操作台!$F$4)*(模板库!$E$2:$E$1000="item")),7),""),IF(OR(_xlpm.v="",_xlpm.v=0),"",_xlpm.v)),IF(操作台!$B$4="接龙导入",IFERROR(INDEX(计算区!$M$5:$M$25,7),""),""))} | Q10: =IF($B10="","",_xlfn.LET(_xlpm.m,IF($O10<>"",$O10,$J10),_xlpm.p,IF($P10<>"",$P10,IF($K10="","待定",$K10)),_xlpm.title,IF($L10<>"",$L10,$G10),_xlfn.TEXTJOIN("；",TRUE,IF(_xlpm.title="","缺少标题",""),IF(_xlpm.m="","缺少排程分钟",IF(NOT(ISNUMBER(_xlpm.m)),"排程分钟无效","")),IF(_xlpm.p="待定","负责人待定",""),IF(AND($A10>1,$F10=""),"前序排程中断","")))) -> 负责人待定 | R10: =IF($B10="","",IF(OR($F10="",IF($O10<>"",NOT(ISNUMBER($O10)),NOT(ISNUMBER($J10)))),"",$F10+IF($O10<>"",$O10,$J10)/1440)) -> 0.81944444 | S10: =IF($B10="",0,1) -> 1
A11: 8 | B11: {=IF(操作台!$B$4="议程模板",_xlfn.LET(_xlpm.v,IFERROR(INDEX(_xlfn._xlws.FILTER(模板库!$D$2:$D$1000,(模板库!$B$2:$B$1000=操作台!$F$4)*(模板库!$E$2:$E$1000="item")),8),""),IF(OR(_xlpm.v="",_xlpm.v=0),"",_xlpm.v)),IF(操作台!$B$4="接龙导入",IFERROR(INDEX(计算区!$F$5:$F$25,8),""),IF(COUNTA($L11:$P11)>0,"manual-"&TEXT($A11,"00"),"")))} -> i-grammar-declare | C11: {=IF(操作台!$B$4="议程模板",_xlfn.LET(_xlpm.v,IFERROR(INDEX(_xlfn._xlws.FILTER(模板库!$F$2:$F$1000,(模板库!$B$2:$B$1000=操作台!$F$4)*(模板库!$E$2:$E$1000="item")),8),""),IF(OR(_xlpm.v="",_xlpm.v=0),"",_xlpm.v)),IF(操作台!$B$4="接龙导入",IFERROR(INDEX(计算区!$G$5:$G$25,8),""),IF(COUNTA($L11:$P11)>0,1,"")))} -> 1 | D11: {=IF(操作台!$B$4="议程模板",_xlfn.LET(_xlpm.v,IFERROR(INDEX(_xlfn._xlws.FILTER(模板库!$G$2:$G$1000,(模板库!$B$2:$B$1000=操作台!$F$4)*(模板库!$E$2:$E$1000="item")),8),""),IF(OR(_xlpm.v="",_xlpm.v=0),"",_xlpm.v)),IF(操作台!$B$4="接龙导入",IFERROR(INDEX(计算区!$H$5:$H$25,8),""),IF(COUNTA($L11:$P11)>0,"手工议程","")))} -> 开场环节 | E11: {=IF(操作台!$B$4="议程模板",_xlfn.LET(_xlpm.v,IFERROR(INDEX(_xlfn._xlws.FILTER(模板库!$M$2:$M$1000,(模板库!$B$2:$B$1000=操作台!$F$4)*(模板库!$E$2:$E$1000="item")),8),""),IF(OR(_xlpm.v="",_xlpm.v=0),"",_xlpm.v)),IF(操作台!$B$4="接龙导入",IFERROR(INDEX(计算区!$N$5:$N$25,8),""),IF(COUNTA($L11:$P11)>0,"plain","")))} -> plain | F11: =IF($B11="","",IF(COUNTIF($Q$4:$Q10,"*排程*")>0,"",IF(COUNTIF($B$4:$B10,"<>")=0,IF(操作台!$B$4="接龙导入",IF(计算区!$E$7<>"",计算区!$E$7,操作台!$F$10),操作台!$F$10),MAX($R$4:$R10)))) -> 0.81944444 | G11: {=IF(操作台!$B$4="议程模板",_xlfn.LET(_xlpm.v,IFERROR(INDEX(_xlfn._xlws.FILTER(模板库!$H$2:$H$1000,(模板库!$B$2:$B$1000=操作台!$F$4)*(模板库!$E$2:$E$1000="item")),8),""),IF(OR(_xlpm.v="",_xlpm.v=0),"",_xlpm.v)),IF(操作台!$B$4="接龙导入",IFERROR(INDEX(计算区!$I$5:$I$25,8),""),""))} -> 语法官宣言 | H11: {=IF(操作台!$B$4="议程模板",_xlfn.LET(_xlpm.v,IFERROR(INDEX(_xlfn._xlws.FILTER(模板库!$I$2:$I$1000,(模板库!$B$2:$B$1000=操作台!$F$4)*(模板库!$E$2:$E$1000="item")),8),""),IF(OR(_xlpm.v="",_xlpm.v=0),"",_xlpm.v)),IF(操作台!$B$4="接龙导入","",""))} | I11: {=IF(操作台!$B$4="议程模板",_xlfn.LET(_xlpm.v,IFERROR(INDEX(_xlfn._xlws.FILTER(模板库!$J$2:$J$1000,(模板库!$B$2:$B$1000=操作台!$F$4)*(模板库!$E$2:$E$1000="item")),8),""),IF(OR(_xlpm.v="",_xlpm.v=0),"",_xlpm.v)),IF(操作台!$B$4="接龙导入",IFERROR(INDEX(计算区!$J$5:$J$25,8),""),""))} -> 2 | J11: {=IF(操作台!$B$4="议程模板",_xlfn.LET(_xlpm.v,IFERROR(INDEX(_xlfn._xlws.FILTER(模板库!$K$2:$K$1000,(模板库!$B$2:$B$1000=操作台!$F$4)*(模板库!$E$2:$E$1000="item")),8),""),IF(OR(_xlpm.v="",_xlpm.v=0),"",_xlpm.v)),IF(操作台!$B$4="接龙导入",IFERROR(INDEX(计算区!$K$5:$K$25,8),""),""))} -> 2 | K11: {=IF(操作台!$B$4="议程模板",_xlfn.LET(_xlpm.v,IFERROR(INDEX(_xlfn._xlws.FILTER(模板库!$L$2:$L$1000,(模板库!$B$2:$B$1000=操作台!$F$4)*(模板库!$E$2:$E$1000="item")),8),""),IF(OR(_xlpm.v="",_xlpm.v=0),"",_xlpm.v)),IF(操作台!$B$4="接龙导入",IFERROR(INDEX(计算区!$M$5:$M$25,8),""),""))} | Q11: =IF($B11="","",_xlfn.LET(_xlpm.m,IF($O11<>"",$O11,$J11),_xlpm.p,IF($P11<>"",$P11,IF($K11="","待定",$K11)),_xlpm.title,IF($L11<>"",$L11,$G11),_xlfn.TEXTJOIN("；",TRUE,IF(_xlpm.title="","缺少标题",""),IF(_xlpm.m="","缺少排程分钟",IF(NOT(ISNUMBER(_xlpm.m)),"排程分钟无效","")),IF(_xlpm.p="待定","负责人待定",""),IF(AND($A11>1,$F11=""),"前序排程中断","")))) -> 负责人待定 | R11: =IF($B11="","",IF(OR($F11="",IF($O11<>"",NOT(ISNUMBER($O11)),NOT(ISNUMBER($J11)))),"",$F11+IF($O11<>"",$O11,$J11)/1440)) -> 0.82083333 | S11: =IF($B11="",0,1) -> 1
A12: 9 | B12: {=IF(操作台!$B$4="议程模板",_xlfn.LET(_xlpm.v,IFERROR(INDEX(_xlfn._xlws.FILTER(模板库!$D$2:$D$1000,(模板库!$B$2:$B$1000=操作台!$F$4)*(模板库!$E$2:$E$1000="item")),9),""),IF(OR(_xlpm.v="",_xlpm.v=0),"",_xlpm.v)),IF(操作台!$B$4="接龙导入",IFERROR(INDEX(计算区!$F$5:$F$25,9),""),IF(COUNTA($L12:$P12)>0,"manual-"&TEXT($A12,"00"),"")))} -> i-impromptu-rule | C12: {=IF(操作台!$B$4="议程模板",_xlfn.LET(_xlpm.v,IFERROR(INDEX(_xlfn._xlws.FILTER(模板库!$F$2:$F$1000,(模板库!$B$2:$B$1000=操作台!$F$4)*(模板库!$E$2:$E$1000="item")),9),""),IF(OR(_xlpm.v="",_xlpm.v=0),"",_xlpm.v)),IF(操作台!$B$4="接龙导入",IFERROR(INDEX(计算区!$G$5:$G$25,9),""),IF(COUNTA($L12:$P12)>0,1,"")))} -> 2 | D12: {=IF(操作台!$B$4="议程模板",_xlfn.LET(_xlpm.v,IFERROR(INDEX(_xlfn._xlws.FILTER(模板库!$G$2:$G$1000,(模板库!$B$2:$B$1000=操作台!$F$4)*(模板库!$E$2:$E$1000="item")),9),""),IF(OR(_xlpm.v="",_xlpm.v=0),"",_xlpm.v)),IF(操作台!$B$4="接龙导入",IFERROR(INDEX(计算区!$H$5:$H$25,9),""),IF(COUNTA($L12:$P12)>0,"手工议程","")))} -> 即兴演讲 | E12: {=IF(操作台!$B$4="议程模板",_xlfn.LET(_xlpm.v,IFERROR(INDEX(_xlfn._xlws.FILTER(模板库!$M$2:$M$1000,(模板库!$B$2:$B$1000=操作台!$F$4)*(模板库!$E$2:$E$1000="item")),9),""),IF(OR(_xlpm.v="",_xlpm.v=0),"",_xlpm.v)),IF(操作台!$B$4="接龙导入",IFERROR(INDEX(计算区!$N$5:$N$25,9),""),IF(COUNTA($L12:$P12)>0,"plain","")))} -> impromptu | F12: =IF($B12="","",IF(COUNTIF($Q$4:$Q11,"*排程*")>0,"",IF(COUNTIF($B$4:$B11,"<>")=0,IF(操作台!$B$4="接龙导入",IF(计算区!$E$7<>"",计算区!$E$7,操作台!$F$10),操作台!$F$10),MAX($R$4:$R11)))) -> 0.82083333 | G12: {=IF(操作台!$B$4="议程模板",_xlfn.LET(_xlpm.v,IFERROR(INDEX(_xlfn._xlws.FILTER(模板库!$H$2:$H$1000,(模板库!$B$2:$B$1000=操作台!$F$4)*(模板库!$E$2:$E$1000="item")),9),""),IF(OR(_xlpm.v="",_xlpm.v=0),"",_xlpm.v)),IF(操作台!$B$4="接龙导入",IFERROR(INDEX(计算区!$I$5:$I$25,9),""),""))} -> 即兴主持介绍规则 | H12: {=IF(操作台!$B$4="议程模板",_xlfn.LET(_xlpm.v,IFERROR(INDEX(_xlfn._xlws.FILTER(模板库!$I$2:$I$1000,(模板库!$B$2:$B$1000=操作台!$F$4)*(模板库!$E$2:$E$1000="item")),9),""),IF(OR(_xlpm.v="",_xlpm.v=0),"",_xlpm.v)),IF(操作台!$B$4="接龙导入","",""))} | I12: {=IF(操作台!$B$4="议程模板",_xlfn.LET(_xlpm.v,IFERROR(INDEX(_xlfn._xlws.FILTER(模板库!$J$2:$J$1000,(模板库!$B$2:$B$1000=操作台!$F$4)*(模板库!$E$2:$E$1000="item")),9),""),IF(OR(_xlpm.v="",_xlpm.v=0),"",_xlpm.v)),IF(操作台!$B$4="接龙导入",IFERROR(INDEX(计算区!$J$5:$J$25,9),""),""))} -> 2 | J12: {=IF(操作台!$B$4="议程模板",_xlfn.LET(_xlpm.v,IFERROR(INDEX(_xlfn._xlws.FILTER(模板库!$K$2:$K$1000,(模板库!$B$2:$B$1000=操作台!$F$4)*(模板库!$E$2:$E$1000="item")),9),""),IF(OR(_xlpm.v="",_xlpm.v=0),"",_xlpm.v)),IF(操作台!$B$4="接龙导入",IFERROR(INDEX(计算区!$K$5:$K$25,9),""),""))} -> 2 | K12: {=IF(操作台!$B$4="议程模板",_xlfn.LET(_xlpm.v,IFERROR(INDEX(_xlfn._xlws.FILTER(模板库!$L$2:$L$1000,(模板库!$B$2:$B$1000=操作台!$F$4)*(模板库!$E$2:$E$1000="item")),9),""),IF(OR(_xlpm.v="",_xlpm.v=0),"",_xlpm.v)),IF(操作台!$B$4="接龙导入",IFERROR(INDEX(计算区!$M$5:$M$25,9),""),""))} | Q12: =IF($B12="","",_xlfn.LET(_xlpm.m,IF($O12<>"",$O12,$J12),_xlpm.p,IF($P12<>"",$P12,IF($K12="","待定",$K12)),_xlpm.title,IF($L12<>"",$L12,$G12),_xlfn.TEXTJOIN("；",TRUE,IF(_xlpm.title="","缺少标题",""),IF(_xlpm.m="","缺少排程分钟",IF(NOT(ISNUMBER(_xlpm.m)),"排程分钟无效","")),IF(_xlpm.p="待定","负责人待定",""),IF(AND($A12>1,$F12=""),"前序排程中断","")))) -> 负责人待定 | R12: =IF($B12="","",IF(OR($F12="",IF($O12<>"",NOT(ISNUMBER($O12)),NOT(ISNUMBER($J12)))),"",$F12+IF($O12<>"",$O12,$J12)/1440)) -> 0.82222222 | S12: =IF($B12="",0,1) -> 1
